Workbook

Sheet 1_RAW_CORRELATIONS
A2: frame_id | B2: second | C2: scene_description | D2: frame_image | E2: ATT | F2: ATT | G2: ATT | H2: ATT | I2: ATT | J2: ATT | K2: ATT | L2: ATT | M2: AFF_A | N2: AFF_A | O2: AFF_A | P2: AFF_A | Q2: AFF_A | R2: AFF_V | S2: AFF_V | T2: AFF_V | U2: AFF_V | V2: AFF_V | W2: MEM | X2: MEM | Y2: MEM | Z2: MEM | AA2: MEM | AB2: MEM | AC2: MEM | AD2: REW | AE2: REW | AF2: REW | AG2: REW | AH2: REW | AI2: REW | AJ2: REW | AK2: REW | AL2: REW | AM2: SOC | AN2: SOC | AO2: SOC | AP2: SOC | AQ2: SOC | AR2: SOC | AS2: SOC | AT2: SOC | AU2: COG_CL | AV2: COG_CL | AW2: COG_CL | AX2: COG_CL | AY2: COG_LD | AZ2: COG_LD | BA2: COG_LD | BB2: COG_LD | BC2: COG_LD
A3: frame_id | B3: second | C3: scene_description | D3: frame_image | E3: attention | F3: visual_attention | G3: attentional | H3: orienting | I3: target_detection | J3: salience | K3: visual_stimuli | L3: distractor | M3: arousal | N3: affective | O3: emotional | P3: emotional_stimuli | Q3: emotional_responses | R3: valence | S3: negative_affect | T3: disgust | U3: fear | V3: anxiety | W3: encoding | X3: subsequent_memory | Y3: episodic_memory | Z3: semantic_memory | AA3: recall | AB3: recognition | AC3: familiarity | AD3: reward | AE3: reward_anticipation | AF3: motivation | AG3: value | AH3: incentive | AI3: preference | AJ3: approach | AK3: monetary_reward | AL3: craving | AM3: social_cognition | AN3: mentalizing | AO3: theory_mind | AP3: face | AQ3: gaze | AR3: self_referential | AS3: empathy | AT3: social | AU3: language | AV3: semantic | AW3: sentence_comprehension | AX3: comprehension | AY3: working_memory | AZ3: cognitive_control | BA3: executive_function | BB3: inhibition | BC3: task_difficulty
A4: F01 | B4: 1 | C4: Who | E4: 0.25462187 | F4: 0.25933681 | G4: 0.27299801 | H4: 0.15189393 | I4: 0.060450641 | J4: -0.11095806 | K4: 0.302078 | L4: 0.17150438 | M4: -0.12528106 | N4: -0.26618215 | O4: -0.21741826 | P4: -0.093908734 | Q4: -0.10423547 | R4: -0.16753678 | S4: -0.20125295 | T4: 0.021766857 | U4: -0.10667446 | V4: -0.15202765 | W4: 0.17986863 | X4: 0.023675304 | Y4: -0.089165334 | Z4: -0.19111586 | AA4: -0.17554003 | AB4: 0.12659412 | AC4: 0.051920994 | AD4: -0.1052073 | AE4: 0.062305541 | AF4: -0.051684691 | AG4: -0.11675532 | AH4: -0.014871127 | AI4: 0.17588566 | AJ4: -0.073932438 | AK4: 0.0049113332 | AL4: -0.038425887 | AM4: -0.32476391 | AN4: -0.31821749 | AO4: -0.41284108 | AP4: 0.18169557 | AQ4: 0.18693222 | AR4: -0.31188892 | AS4: -0.24438079 | AT4: -0.37871774 | AU4: -0.072642638 | AV4: -0.11231794 | AW4: -0.10628568 | AX4: -0.21364287 | AY4: 0.17046375 | AZ4: -0.06733896 | BA4: 0.0031678533 | BB4: -0.078332854 | BC4: 0.14582554
A5: F02 | B5: 2 | C5: Who could have thought, | E5: 0.25132678 | F5: 0.2200435 | G5: 0.26445247 | H5: 0.18291465 | I5: 0.10927703 | J5: -0.15965101 | K5: 0.26946387 | L5: 0.15943007 | M5: -0.1418888 | N5: -0.25270925 | O5: -0.25745528 | P5: -0.14553683 | Q5: -0.08125111 | R5: -0.20128511 | S5: -0.21516773 | T5: -0.047777049 | U5: -0.14553229 | V5: -0.18957345 | W5: 0.058816311 | X5: -0.07337464 | Y5: -0.17395125 | Z5: -0.22346722 | AA5: -0.19612868 | AB5: 0.036411719 | AC5: -0.033634938 | AD5: -0.13635016 | AE5: 0.03415356 | AF5: -0.074791232 | AG5: -0.15650081 | AH5: -0.040773535 | AI5: 0.16997309 | AJ5: -0.092641224 | AK5: -0.022350406 | AL5: -0.082809008 | AM5: -0.3140323 | AN5: -0.3121238 | AO5: -0.40914199 | AP5: 0.073028472 | AQ5: 0.16671021 | AR5: -0.34787768 | AS5: -0.22561803 | AT5: -0.3908827 | AU5: 0.02302262 | AV5: -0.11090965 | AW5: -0.020772478 | AX5: -0.12371519 | AY5: 0.17064825 | AZ5: -0.034538877 | BA5: -0.0098938322 | BB5: -0.02590671 | BC5: 0.11770648
A6: F03 | B6: 3 | C6: thought, that the future would be | E6: 0.26482585 | F6: 0.27468631 | G6: 0.2645688 | H6: 0.17121384 | I6: 0.057627908 | J6: -0.14415848 | K6: 0.34861877 | L6: 0.16826986 | M6: -0.1424945 | N6: -0.28042411 | O6: -0.21658125 | P6: -0.094291376 | Q6: -0.094029139 | R6: -0.15679023 | S6: -0.22022198 | T6: 0.010750076 | U6: -0.11655866 | V6: -0.18870225 | W6: 0.18572259 | X6: 0.03072136 | Y6: -0.083276159 | Z6: -0.15949395 | AA6: -0.16170632 | AB6: 0.18411768 | AC6: 0.074222357 | AD6: -0.15180777 | AE6: 0.041919838 | AF6: -0.080614908 | AG6: -0.15597847 | AH6: -0.053364698 | AI6: 0.20651036 | AJ6: -0.095509174 | AK6: -0.031997822 | AL6: -0.04850787 | AM6: -0.26403521 | AN6: -0.26120843 | AO6: -0.35282861 | AP6: 0.2447368 | AQ6: 0.23489324 | AR6: -0.30420579 | AS6: -0.22678473 | AT6: -0.31708051 | AU6: 0.012995052 | AV6: -0.042022696 | AW6: -0.054830049 | AX6: -0.12009151 | AY6: 0.14249573 | AZ6: -0.10953379 | BA6: -0.019222248 | BB6: -0.13699695 | BC6: 0.13007868
A7: F04 | B7: 4 | C7: would be exactly like this? | E7: 0.27890363 | F7: 0.29051836 | G7: 0.26454779 | H7: 0.18653063 | I7: 0.055288821 | J7: -0.15777905 | K7: 0.37744111 | L7: 0.16347788 | M7: -0.15075473 | N7: -0.28606307 | O7: -0.21939968 | P7: -0.093397044 | Q7: -0.093195846 | R7: -0.15818865 | S7: -0.22525731 | T7: 0.0093293896 | U7: -0.12356024 | V7: -0.20881617 | W7: 0.17730479 | X7: 0.027614831 | Y7: -0.092397361 | Z7: -0.15681351 | AA7: -0.17171776 | AB7: 0.2005212 | AC7: 0.075399948 | AD7: -0.18496775 | AE7: 0.026620928 | AF7: -0.10254083 | AG7: -0.18344359 | AH7: -0.08126031 | AI7: 0.21809673 | AJ7: -0.10526151 | AK7: -0.057194442 | AL7: -0.058893784 | AM7: -0.23242085 | AN7: -0.22564983 | AO7: -0.31587153 | AP7: 0.27014627 | AQ7: 0.27194272 | AR7: -0.29647951 | AS7: -0.20943717 | AT7: -0.28175035 | AU7: 0.038923788 | AV7: -0.02531231 | AW7: -0.039086606 | AX7: -0.086269823 | AY7: 0.12166951 | AZ7: -0.13749612 | BA7: -0.033968465 | BB7: -0.15962249 | BC7: 0.11817903
A8: F05 | B8: 5 | C8: like this? Concise, | E8: 0.29322772 | F8: 0.30877561 | G8: 0.26992675 | H8: 0.19134718 | I8: 0.045090175 | J8: -0.144996 | K8: 0.39771595 | L8: 0.16120212 | M8: -0.14713988 | N8: -0.2924054 | O8: -0.21883628 | P8: -0.08415797 | Q8: -0.097404127 | R8: -0.16037179 | S8: -0.22478677 | T8: 0.017589418 | U8: -0.1221091 | V8: -0.20398321 | W8: 0.17946991 | X8: 0.029369742 | Y8: -0.084662659 | Z8: -0.15827876 | AA8: -0.18031291 | AB8: 0.20447018 | AC8: 0.078775424 | AD8: -0.18176805 | AE8: 0.032968457 | AF8: -0.09969208 | AG8: -0.1794956 | AH8: -0.080252923 | AI8: 0.2229403 | AJ8: -0.096612814 | AK8: -0.055546935 | AL8: -0.053152602 | AM8: -0.2247248 | AN8: -0.21706416 | AO8: -0.30847764 | AP8: 0.27757915 | AQ8: 0.29015714 | AR8: -0.28424484 | AS8: -0.21202457 | AT8: -0.26982871 | AU8: 0.0085553465 | AV8: -0.042746354 | AW8: -0.056466591 | AX8: -0.10852979 | AY8: 0.11587528 | AZ8: -0.14621958 | BA8: -0.033996732 | BB8: -0.16648932 | BC8: 0.11640968
A9: F06 | B9: 6 | C9: Concise, | E9: 0.31451021 | F9: 0.32961307 | G9: 0.28630625 | H9: 0.207604 | I9: 0.051096406 | J9: -0.16863722 | K9: 0.41598312 | L9: 0.16877058 | M9: -0.16165971 | N9: -0.31100347 | O9: -0.24495484 | P9: -0.10033358 | Q9: -0.11920995 | R9: -0.18457603 | S9: -0.23925418 | T9: 0.0076219509 | U9: -0.14318645 | V9: -0.23176067 | W9: 0.16608679 | X9: 0.017110091 | Y9: -0.10956415 | Z9: -0.17195303 | AA9: -0.20515507 | AB9: 0.20647036 | AC9: 0.075023019 | AD9: -0.21717677 | AE9: 0.017839576 | AF9: -0.12024466 | AG9: -0.21261552 | AH9: -0.10192352 | AI9: 0.21856834 | AJ9: -0.11927221 | AK9: -0.075651419 | AL9: -0.074723271 | AM9: -0.22398284 | AN9: -0.20996636 | AO9: -0.30668396 | AP9: 0.28151382 | AQ9: 0.31893422 | AR9: -0.30163704 | AS9: -0.20385593 | AT9: -0.27393211 | AU9: 0.030637646 | AV9: -0.035487685 | AW9: -0.043318286 | AX9: -0.094216907 | AY9: 0.12666128 | AZ9: -0.15550857 | BA9: -0.04288113 | BB9: -0.1760717 | BC9: 0.12497562
A10: F07 | B10: 7 | C10: perfect, | E10: 0.31645676 | F10: 0.33422166 | G10: 0.28737222 | H10: 0.21059439 | I10: 0.055218681 | J10: -0.17969516 | K10: 0.42027777 | L10: 0.16840033 | M10: -0.17290568 | N10: -0.31868958 | O10: -0.25720272 | P10: -0.10926871 | Q10: -0.12446765 | R10: -0.19366259 | S10: -0.24511457 | T10: -0.0031517773 | U10: -0.15896149 | V10: -0.25278229 | W10: 0.15725953 | X10: 0.0089715004 | Y10: -0.11681683 | Z10: -0.16915511 | AA10: -0.20853297 | AB10: 0.21106393 | AC10: 0.076827347 | AD10: -0.23934355 | AE10: 0.0040622582 | AF10: -0.13596488 | AG10: -0.22892559 | AH10: -0.12034033 | AI10: 0.22035303 | AJ10: -0.13158026 | AK10: -0.090843722 | AL10: -0.089199454 | AM10: -0.21657863 | AN10: -0.19820227 | AO10: -0.29415574 | AP10: 0.27699759 | AQ10: 0.32314727 | AR10: -0.29979405 | AS10: -0.19843339 | AT10: -0.27080871 | AU10: 0.064379632 | AV10: -0.010169075 | AW10: -0.01965524 | AX10: -0.061740501 | AY10: 0.13060066 | AZ10: -0.15876446 | BA10: -0.048045599 | BB10: -0.18708672 | BC10: 0.12855545
A11: F08 | B11: 8 | C11: perfect, that design | E11: 0.31693713 | F11: 0.34081201 | G11: 0.28421808 | H11: 0.21184434 | I11: 0.051029861 | J11: -0.18835176 | K11: 0.42864335 | L11: 0.16869362 | M11: -0.18207388 | N11: -0.32589635 | O11: -0.26276342 | P11: -0.11230343 | Q11: -0.13416189 | R11: -0.19666857 | S11: -0.24746105 | T11: -0.0055801581 | U11: -0.16930469 | V11: -0.26872667 | W11: 0.1626969 | X11: 0.017000499 | Y11: -0.11546687 | Z11: -0.15925509 | AA11: -0.20984534 | AB11: 0.22708435 | AC11: 0.088139371 | AD11: -0.26445072 | AE11: -0.010836601 | AF11: -0.15095337 | AG11: -0.24598073 | AH11: -0.13765488 | AI11: 0.21849613 | AJ11: -0.14409292 | AK11: -0.10793716 | AL11: -0.095043128 | AM11: -0.19715356 | AN11: -0.1714369 | AO11: -0.26258736 | AP11: 0.29187718 | AQ11: 0.33943352 | AR11: -0.28894889 | AS11: -0.18478929 | AT11: -0.24872909 | AU11: 0.088956669 | AV11: 0.018202921 | AW11: -0.0040340161 | AX11: -0.031449752 | AY11: 0.12394947 | AZ11: -0.17370145 | BA11: -0.053658875 | BB11: -0.20603419 | BC11: 0.12856183
A12: F09 | B12: 9 | C12: design would define | E12: 0.27922391 | F12: 0.31650159 | G12: 0.25186154 | H12: 0.18727411 | I12: 0.051136754 | J12: -0.19857322 | K12: 0.41275444 | L12: 0.15147047 | M12: -0.18396944 | N12: -0.31596919 | O12: -0.25360121 | P12: -0.10857858 | Q12: -0.12124657 | R12: -0.18299971 | S12: -0.25118552 | T12: -0.012955477 | U12: -0.17406793 | V12: -0.28065382 | W12: 0.1565175 | X12: 0.019112018 | Y12: -0.1068745 | Z12: -0.1365463 | AA12: -0.19109943 | AB12: 0.23999359 | AC12: 0.096568951 | AD12: -0.27423184 | AE12: -0.021702103 | AF12: -0.16011391 | AG12: -0.24561886 | AH12: -0.15068583 | AI12: 0.22254118 | AJ12: -0.14509258 | AK12: -0.12162732 | AL12: -0.09970978 | AM12: -0.17023984 | AN12: -0.1479515 | AO12: -0.23073857 | AP12: 0.29919338 | AQ12: 0.32250474 | AR12: -0.27226472 | AS12: -0.17743489 | AT12: -0.22297011 | AU12: 0.15135734 | AV12: 0.073176776 | AW12: 0.034728498 | AX12: 0.035069314 | AY12: 0.10685621 | AZ12: -0.18656155 | BA12: -0.062926557 | BB12: -0.23029522 | BC12: 0.11607915
A13: F10 | B13: 10 | C13: define functionality, | E13: 0.26362004 | F13: 0.30269311 | G13: 0.23806444 | H13: 0.17992626 | I13: 0.048082436 | J13: -0.20750781 | K13: 0.40533532 | L13: 0.14612954 | M13: -0.18695951 | N13: -0.30672199 | O13: -0.24018727 | P13: -0.10264676 | Q13: -0.11567609 | R13: -0.16936319 | S13: -0.24638929 | T13: -0.011526115 | U13: -0.17076321 | V13: -0.28786381 | W13: 0.16039691 | X13: 0.03088632 | Y13: -0.10162188 | Z13: -0.11794765 | AA13: -0.17951812 | AB13: 0.25862974 | AC13: 0.10774453 | AD13: -0.28735152 | AE13: -0.035617995 | AF13: -0.16791977 | AG13: -0.25417058 | AH13: -0.16280552 | AI13: 0.21919879 | AJ13: -0.15526463 | AK13: -0.13520594 | AL13: -0.10406221 | AM13: -0.13963435 | AN13: -0.11609426 | AO13: -0.18980575 | AP13: 0.32147192 | AQ13: 0.32510669 | AR13: -0.25979902 | AS13: -0.15677921 | AT13: -0.1863845 | AU13: 0.19266696 | AV13: 0.11381683 | AW13: 0.058443752 | AX13: 0.081053961 | AY13: 0.09613008 | AZ13: -0.19462687 | BA13: -0.066958142 | BB13: -0.24242401 | BC13: 0.11263214
A14: F11 | B14: 11 | C14: functionality, and technology | E14: 0.27106745 | F14: 0.30072748 | G14: 0.2432021 | H14: 0.18785386 | I14: 0.042212249 | J14: -0.19687139 | K14: 0.40605146 | L14: 0.14623867 | M14: -0.19106679 | N14: -0.299857 | O14: -0.2271453 | P14: -0.091141017 | Q14: -0.10646941 | R14: -0.1604868 | S14: -0.23530496 | T14: -0.0074678551 | U14: -0.16847924 | V14: -0.28807157 | W14: 0.16090439 | X14: 0.039114227 | Y14: -0.092002497 | Z14: -0.11169238 | AA14: -0.17626409 | AB14: 0.26695499 | AC14: 0.11119201 | AD14: -0.29460316 | AE14: -0.045743719 | AF14: -0.17450082 | AG14: -0.25777688 | AH14: -0.17436732 | AI14: 0.21723864 | AJ14: -0.15692838 | AK14: -0.1451228 | AL14: -0.10752358 | AM14: -0.10856382 | AN14: -0.078222142 | AO14: -0.14534764 | AP14: 0.33647959 | AQ14: 0.33846066 | AR14: -0.23338668 | AS14: -0.13778298 | AT14: -0.14663395 | AU14: 0.19265748 | AV14: 0.12253688 | AW14: 0.060789431 | AX14: 0.093053487 | AY14: 0.091053048 | AZ14: -0.18766128 | BA14: -0.060992845 | BB14: -0.23115082 | BC14: 0.11632624
A15: F12 | B15: 12 | C15: technology would become an element | E15: 0.26845032 | F15: 0.30550794 | G15: 0.23666615 | H15: 0.18333489 | I15: 0.038820534 | J15: -0.19861917 | K15: 0.40853268 | L15: 0.1428052 | M15: -0.18770881 | N15: -0.29221104 | O15: -0.21785898 | P15: -0.086379271 | Q15: -0.10992338 | R15: -0.15424583 | S15: -0.23118838 | T15: 0.0018023713 | U15: -0.15960937 | V15: -0.28240215 | W15: 0.16094581 | X15: 0.045053441 | Y15: -0.098267187 | Z15: -0.10970089 | AA15: -0.18434045 | AB15: 0.27458908 | AC15: 0.11411597 | AD15: -0.30131831 | AE15: -0.049242487 | AF15: -0.17808584 | AG15: -0.26383783 | AH15: -0.17918756 | AI15: 0.21767536 | AJ15: -0.1580965 | AK15: -0.14978706 | AL15: -0.10806202 | AM15: -0.097113968 | AN15: -0.068143297 | AO15: -0.13258333 | AP15: 0.35758146 | AQ15: 0.35510702 | AR15: -0.22962109 | AS15: -0.12542588 | AT15: -0.13051705 | AU15: 0.18989491 | AV15: 0.11966407 | AW15: 0.052532674 | AX15: 0.092329609 | AY15: 0.07134617 | AZ15: -0.20692029 | BA15: -0.073355785 | BB15: -0.23988481 | BC15: 0.11000469
... A23: F20 | B23: 20 | C23: of the future. | E23: 0.39291297 | F23: 0.33215125 | G23: 0.34224684 | H23: 0.28252524 | I23: 0.10555921 | J23: -0.18567091 | K23: 0.25866322 | L23: 0.20507762 | M23: -0.28949801 | N23: -0.35394812 | O23: -0.36362537 | P23: -0.23153874 | Q23: -0.15582503 | R23: -0.30241502 | S23: -0.18672449 | T23: -0.19443849 | U23: -0.30920529 | V23: -0.31869908 | W23: 0.042406719 | X23: -0.086569949 | Y23: -0.10740525 | Z23: -0.17406285 | AA23: -0.16494157 | AB23: 0.091521716 | AC23: 0.026425503 | AD23: -0.34943939 | AE23: -0.11155566 | AF23: -0.22112907 | AG23: -0.31475485 | AH23: -0.2088155 | AI23: 0.12351744 | AJ23: -0.19250771 | AK23: -0.17117126 | AL23: -0.16114713 | AM23: -0.15972102 | AN23: -0.069668073 | AO23: -0.13791727 | AP23: 0.02834538 | AQ23: 0.24549122 | AR23: -0.18013018 | AS23: -0.13221909 | AT23: -0.25407487 | AU23: 0.088602851 | AV23: -0.0051141101 | AW23: 0.086792141 | AX23: 0.011682916 | AY23: 0.22965438 | AZ23: 0.016755721 | BA23: 0.034022926 | BB23: -0.035465987 | BC23: 0.21092888

Sheet README
B2: NCD · Neurosemantic Creative Diagnostics — Структура файла
B4: ЛИСТ | D4: СОДЕРЖАНИЕ | H4: КОМУ
B5: 1_RAW_CORRELATIONS | D5: Сырые Pearson r по каждому терму Neurosynth для каждого кадра. Сюда аналитик вставляет данные из TRIBE. | H5: Аналитик — заполняет
B6: 2_FRAME_MARKUP | D6: Разметка кадров: какой тег (BRAND/OFFER/CTA/FACE/PRODUCT/HOOK) присвоен каждому кадру. Заполняется вручную перед анализом. | H6: Аналитик — заполняет вручную
B7: 3_INDEX_SCORES | D7: Расчёт индексов по кадрам: взвешенные r, trimmed mean, штрафы. Формулы автоматически тянут данные из листов 1 и 2. | H7: Формулы — не редактировать
B8: 4_WINDOW_AGGREGATES | D8: Агрегаты по временным окнам: Hook, Brand, Offer, CTA, AUC, Peak, Finale. Основа для отчёта. | H8: Формулы — читать и интерпретировать
B9: 5_WEIGHTS_REF | D9: Справочник весов: какой терм входит в какой индекс с каким весом. Аналитик может корректировать веса здесь — формулы в листе 3 тянут отсюда. | H9: Аналитик — может менять веса
B11: Пайплайн: как данные движутся между листами
B12: TRIBE + Neurosynth → Pearson r по термам → [1_RAW_CORRELATIONS] + разметка кадров → [2_FRAME_MARKUP] → расчёт индексов → [3_INDEX_SCORES] → агрегаты по окнам → [4_WINDOW_AGGREGATES] → отчёт / дашборд
B16: Ключевые правила заполнения
B17: 1. Лист 1 (RAW): один кадр = одна строка. Секунда заполняется как число (1, 2, 3...). r-значения — числа от -1 до +1.
B18: 2. Лист 2 (MARKUP): теги вводятся через запятую если кадр попадает в несколько окон. Пример: BRAND,FACE. Строго из списка: HOOK / BRAND / PRODUCT / OFFER / CTA / LOGO.
B19: 3. Лист 3 (INDEX_SCORES): не редактировать вручную. Только формулы. При добавлении новых кадров — протянуть формулы вниз.
B20: 4. Лист 5 (WEIGHTS): единственное место, где можно менять веса. После изменения пересчитать лист 3.
B21: 5. Нормировка: z-score считается в листе 4. Phase 1 = z-score внутри ролика. При накоплении базы — переходить к перцентилям.
B23: ⚠ Финальный состав индексов v1.3
B24: Изменения v1.3 (последняя итерация): • AFF-A: терм 'emotion' заменён на 'emotional_stimuli' + 'emotional_responses' (вес 0.6 каждый) — более специфичные термы из финальной библиотеки • AFF-V: 'emotional_valence' НЕ добавлен (избыточен относительно 'valence'). Субиндекс = valence (якорь, вес 1.0) минус штрафы (negative_affect 1.2, disgust 1.5, fear 0.6, anxiety 0.5) ВАЖНО — интерпретация AFF-V: association map терма 'valence' не кодирует знак направления (позитив/негатив) сам по себе — она показывает только то, что валентность как конструкт обрабатывается. Реальный сигнал о знаке дают штрафные термы. Поэтому AFF-V — это ИНДЕКС НЕГАТИВНОЙ ОКРАСКИ, а не симметричная шкала позитив↔негатив. Высокое значение = низкий уровень негативных паттернов (не значит 'позитивно'). Низкое/отрицательное = присутствуют негативные паттерны.
B32: Полные названия индексов (v1.3)
B33: ATT | D33: ATT — Внимание и захват взгляда | G33: Привлекает ли кадр взгляд, активируется ли рефлекторная и управляемая ориентировка
B34: AFF-A | D34: AFF-A — Эмоциональная интенсивность (Arousal) | G34: Насколько сильно кадр активирует аффективную систему — без учёта знака
B35: AFF-V | D35: AFF-V — Негативная эмоциональная окраска | G35: Присутствуют ли в кадре паттерны негативного аффекта (страх, отвращение, тревога)
B36: MEM | D36: MEM — Потенциал запоминания | G36: Насколько кадр похож на паттерны кодирования и последующего воспроизведения в памяти
B37: REW | D37: REW — Воспринимаемая ценность и мотивация | G37: Выглядит ли продукт/оффер ценным, желанным, мотивирующим к действию
B38: SOC | D38: SOC — Социальный резонанс | G38: Активируется ли «социальный мозг»: лица, эмпатия, самоидентификация
B39: COG-CL | D39: COG-CL — Ясность сообщения | G39: Насколько легко обрабатывается смысл вербального/нарративного сообщения (выше = понятнее)
B40: COG-LD | D40: COG-LD — Когнитивная нагрузка | G40: Требует ли кадр повышенных управляющих усилий мозга (выше = тяжелее воспринимается)

Sheet 3_INDEX_SCORES
A1: 3_INDEX_SCORES — Расчёт индексов по кадрам (формулы — не редактировать)
A2: Каждая строка = один кадр. Индексы считаются как AVERAGE взвешенных r по ядровым термам минус штрафы. z-score считается на фактическом количестве кадров.
A3: frame_id | B3: second | C3: tags | D3: ATT Внимание | E3: AFF-A Интенсивность | F3: AFF-V Негативность | G3: MEM Запоминание | H3: REW Ценность | I3: SOC Социальность | J3: COG-CL Ясность | K3: COG-LD Нагрузка | L3: z_ATT | M3: z_AFF_A | N3: z_AFF_V | O3: z_MEM | P3: z_REW | Q3: z_SOC | R3: z_COG_CL | S3: z_COG_LD
A4: ='1_RAW_CORRELATIONS'!A4 -> F01 | B4: ='1_RAW_CORRELATIONS'!B4 -> 1 | C4: =IF('2_FRAME_MARKUP'!E4=1,"HOOK ","" )&IF('2_FRAME_MARKUP'!F4=1,"BRAND ","" )&IF('2_FRAME_MARKUP'!G4=1,"PRODUCT ","" )&IF('2_FRAME_MARKUP'!H4=1,"OFFER ","" )&IF('2_FRAME_MARKUP'!I4=1,"CTA ","" )&IF('2_FRAME_MARKUP'!J4=1,"LOGO ","" ) | D4: =AVERAGE('1_RAW_CORRELATIONS'!E4*1,'1_RAW_CORRELATIONS'!F4*1.2,'1_RAW_CORRELATIONS'!G4*1,'1_RAW_CORRELATIONS'!H4*1.1,'1_RAW_CORRELATIONS'!I4*1,'1_RAW_CORRELATIONS'!J4*1.2,'1_RAW_CORRELATIONS'!K4*0.7)-(MAX(0,'1_RAW_CORRELATIONS'!L4)*1) -> -0.0079810984 | E4: =AVERAGE('1_RAW_CORRELATIONS'!M4*1.3,'1_RAW_CORRELATIONS'!N4*1,'1_RAW_CORRELATIONS'!O4*0.5,'1_RAW_CORRELATIONS'!P4*0.6,'1_RAW_CORRELATIONS'!Q4*0.6)-0 -> -0.13132864 | F4: =AVERAGE('1_RAW_CORRELATIONS'!R4*1)-(MAX(0,'1_RAW_CORRELATIONS'!S4)*1.2+MAX(0,'1_RAW_CORRELATIONS'!T4)*1.5+MAX(0,'1_RAW_CORRELATIONS'!U4)*0.6+MAX(0,'1_RAW_CORRELATIONS'!V4)*0.5) -> -0.20018706 | G4: =AVERAGE('1_RAW_CORRELATIONS'!W4*1.5,'1_RAW_CORRELATIONS'!X4*1.3,'1_RAW_CORRELATIONS'!Y4*1,'1_RAW_CORRELATIONS'!Z4*1,'1_RAW_CORRELATIONS'!AA4*1.1,'1_RAW_CORRELATIONS'!AB4*1,'1_RAW_CORRELATIONS'!AC4*0.9)-0 -> 7.5518808e-05 | H4: =AVERAGE('1_RAW_CORRELATIONS'!AD4*1,'1_RAW_CORRELATIONS'!AE4*1.2,'1_RAW_CORRELATIONS'!AF4*1.1,'1_RAW_CORRELATIONS'!AG4*1.2,'1_RAW_CORRELATIONS'!AH4*1,'1_RAW_CORRELATIONS'!AI4*1,'1_RAW_CORRELATIONS'!AJ4*1.1,'1_RAW_CORRELATIONS'!AK4*1.1,'1_RAW_CORRELATIONS'!AL4*0.9)-0 -> -0.019654687 | I4: =AVERAGE('1_RAW_CORRELATIONS'!AM4*1,'1_RAW_CORRELATIONS'!AN4*1.2,'1_RAW_CORRELATIONS'!AO4*1,'1_RAW_CORRELATIONS'!AP4*1.3,'1_RAW_CORRELATIONS'!AQ4*1.2,'1_RAW_CORRELATIONS'!AR4*1.3,'1_RAW_CORRELATIONS'!AS4*1.1,'1_RAW_CORRELATIONS'!AT4*0.7)-0 -> -0.19979 | J4: =AVERAGE('1_RAW_CORRELATIONS'!AU4*1.2,'1_RAW_CORRELATIONS'!AV4*1.2,'1_RAW_CORRELATIONS'!AW4*1.3,'1_RAW_CORRELATIONS'!AX4*1)-0 -> -0.14344174 | K4: =AVERAGE('1_RAW_CORRELATIONS'!AY4*1.3,'1_RAW_CORRELATIONS'!AZ4*1.1,'1_RAW_CORRELATIONS'!BA4*1,'1_RAW_CORRELATIONS'!BB4*0.9,'1_RAW_CORRELATIONS'!BC4*1.2)-0 -> 0.051037789 | L4: =IFERROR((D4-AVERAGE(D$4:D$23))/STDEV(D$4:D$23),0) -> -2.179243 | M4: =IFERROR((E4-AVERAGE(E$4:E$23))/STDEV(E$4:E$23),0) -> 1.3347861 | N4: =IFERROR((F4-AVERAGE(F$4:F$23))/STDEV(F$4:F$23),0) -> -0.27119055 | O4: =IFERROR((G4-AVERAGE(G$4:G$23))/STDEV(G$4:G$23),0) -> -0.32933615 | P4: =IFERROR((H4-AVERAGE(H$4:H$23))/STDEV(H$4:H$23),0) -> 2.0901345 | Q4: =IFERROR((I4-AVERAGE(I$4:I$23))/STDEV(I$4:I$23),0) -> -1.9525015 | R4: =IFERROR((J4-AVERAGE(J$4:J$23))/STDEV(J$4:J$23),0) -> -2.0244532 | S4: =IFERROR((K4-AVERAGE(K$4:K$23))/STDEV(K$4:K$23),0) -> 1.1455824
A5: ='1_RAW_CORRELATIONS'!A5 -> F02 | B5: ='1_RAW_CORRELATIONS'!B5 -> 2 | C5: =IF('2_FRAME_MARKUP'!E5=1,"HOOK ","" )&IF('2_FRAME_MARKUP'!F5=1,"BRAND ","" )&IF('2_FRAME_MARKUP'!G5=1,"PRODUCT ","" )&IF('2_FRAME_MARKUP'!H5=1,"OFFER ","" )&IF('2_FRAME_MARKUP'!I5=1,"CTA ","" )&IF('2_FRAME_MARKUP'!J5=1,"LOGO ","" ) | D5: =AVERAGE('1_RAW_CORRELATIONS'!E5*1,'1_RAW_CORRELATIONS'!F5*1.2,'1_RAW_CORRELATIONS'!G5*1,'1_RAW_CORRELATIONS'!H5*1.1,'1_RAW_CORRELATIONS'!I5*1,'1_RAW_CORRELATIONS'!J5*1.2,'1_RAW_CORRELATIONS'!K5*0.7)-(MAX(0,'1_RAW_CORRELATIONS'!L5)*1) -> -0.0040932038 | E5: =AVERAGE('1_RAW_CORRELATIONS'!M5*1.3,'1_RAW_CORRELATIONS'!N5*1,'1_RAW_CORRELATIONS'!O5*0.5,'1_RAW_CORRELATIONS'!P5*0.6,'1_RAW_CORRELATIONS'!Q5*0.6)-0 -> -0.14039302 | F5: =AVERAGE('1_RAW_CORRELATIONS'!R5*1)-(MAX(0,'1_RAW_CORRELATIONS'!S5)*1.2+MAX(0,'1_RAW_CORRELATIONS'!T5)*1.5+MAX(0,'1_RAW_CORRELATIONS'!U5)*0.6+MAX(0,'1_RAW_CORRELATIONS'!V5)*0.5) -> -0.20128511 | G5: =AVERAGE('1_RAW_CORRELATIONS'!W5*1.5,'1_RAW_CORRELATIONS'!X5*1.3,'1_RAW_CORRELATIONS'!Y5*1,'1_RAW_CORRELATIONS'!Z5*1,'1_RAW_CORRELATIONS'!AA5*1.1,'1_RAW_CORRELATIONS'!AB5*1,'1_RAW_CORRELATIONS'!AC5*0.9)-0 -> -0.08774033 | H5: =AVERAGE('1_RAW_CORRELATIONS'!AD5*1,'1_RAW_CORRELATIONS'!AE5*1.2,'1_RAW_CORRELATIONS'!AF5*1.1,'1_RAW_CORRELATIONS'!AG5*1.2,'1_RAW_CORRELATIONS'!AH5*1,'1_RAW_CORRELATIONS'!AI5*1,'1_RAW_CORRELATIONS'!AJ5*1.1,'1_RAW_CORRELATIONS'!AK5*1.1,'1_RAW_CORRELATIONS'!AL5*0.9)-0 -> -0.048584061 | I5: =AVERAGE('1_RAW_CORRELATIONS'!AM5*1,'1_RAW_CORRELATIONS'!AN5*1.2,'1_RAW_CORRELATIONS'!AO5*1,'1_RAW_CORRELATIONS'!AP5*1.3,'1_RAW_CORRELATIONS'!AQ5*1.2,'1_RAW_CORRELATIONS'!AR5*1.3,'1_RAW_CORRELATIONS'!AS5*1.1,'1_RAW_CORRELATIONS'!AT5*0.7)-0 -> -0.22209654 | J5: =AVERAGE('1_RAW_CORRELATIONS'!AU5*1.2,'1_RAW_CORRELATIONS'!AV5*1.2,'1_RAW_CORRELATIONS'!AW5*1.3,'1_RAW_CORRELATIONS'!AX5*1)-0 -> -0.064045964 | K5: =AVERAGE('1_RAW_CORRELATIONS'!AY5*1.3,'1_RAW_CORRELATIONS'!AZ5*1.1,'1_RAW_CORRELATIONS'!BA5*1,'1_RAW_CORRELATIONS'!BB5*0.9,'1_RAW_CORRELATIONS'!BC5*1.2)-0 -> 0.058377571 | L5: =IFERROR((D5-AVERAGE(D$4:D$23))/STDEV(D$4:D$23),0) -> -1.8958293 | M5: =IFERROR((E5-AVERAGE(E$4:E$23))/STDEV(E$4:E$23),0) -> 0.92199798 | N5: =IFERROR((F5-AVERAGE(F$4:F$23))/STDEV(F$4:F$23),0) -> -0.30454104 | O5: =IFERROR((G5-AVERAGE(G$4:G$23))/STDEV(G$4:G$23),0) -> -3.0859538 | P5: =IFERROR((H5-AVERAGE(H$4:H$23))/STDEV(H$4:H$23),0) -> 1.4031181 | Q5: =IFERROR((I5-AVERAGE(I$4:I$23))/STDEV(I$4:I$23),0) -> -2.2861084 | R5: =IFERROR((J5-AVERAGE(J$4:J$23))/STDEV(J$4:J$23),0) -> -0.96857996 | S5: =IFERROR((K5-AVERAGE(K$4:K$23))/STDEV(K$4:K$23),0) -> 1.3127294
A6: ='1_RAW_CORRELATIONS'!A6 -> F03 | B6: ='1_RAW_CORRELATIONS'!B6 -> 3 | C6: =IF('2_FRAME_MARKUP'!E6=1,"HOOK ","" )&IF('2_FRAME_MARKUP'!F6=1,"BRAND ","" )&IF('2_FRAME_MARKUP'!G6=1,"PRODUCT ","" )&IF('2_FRAME_MARKUP'!H6=1,"OFFER ","" )&IF('2_FRAME_MARKUP'!I6=1,"CTA ","" )&IF('2_FRAME_MARKUP'!J6=1,"LOGO ","" ) -> LOGO | D6: =AVERAGE('1_RAW_CORRELATIONS'!E6*1,'1_RAW_CORRELATIONS'!F6*1.2,'1_RAW_CORRELATIONS'!G6*1,'1_RAW_CORRELATIONS'!H6*1.1,'1_RAW_CORRELATIONS'!I6*1,'1_RAW_CORRELATIONS'!J6*1.2,'1_RAW_CORRELATIONS'!K6*0.7)-(MAX(0,'1_RAW_CORRELATIONS'!L6)*1) -> -0.00026638589 | E6: =AVERAGE('1_RAW_CORRELATIONS'!M6*1.3,'1_RAW_CORRELATIONS'!N6*1,'1_RAW_CORRELATIONS'!O6*0.5,'1_RAW_CORRELATIONS'!P6*0.6,'1_RAW_CORRELATIONS'!Q6*0.6)-0 -> -0.13738998 | F6: =AVERAGE('1_RAW_CORRELATIONS'!R6*1)-(MAX(0,'1_RAW_CORRELATIONS'!S6)*1.2+MAX(0,'1_RAW_CORRELATIONS'!T6)*1.5+MAX(0,'1_RAW_CORRELATIONS'!U6)*0.6+MAX(0,'1_RAW_CORRELATIONS'!V6)*0.5) -> -0.17291534 | G6: =AVERAGE('1_RAW_CORRELATIONS'!W6*1.5,'1_RAW_CORRELATIONS'!X6*1.3,'1_RAW_CORRELATIONS'!Y6*1,'1_RAW_CORRELATIONS'!Z6*1,'1_RAW_CORRELATIONS'!AA6*1.1,'1_RAW_CORRELATIONS'!AB6*1,'1_RAW_CORRELATIONS'!AC6*0.9)-0 -> 0.021256055 | H6: =AVERAGE('1_RAW_CORRELATIONS'!AD6*1,'1_RAW_CORRELATIONS'!AE6*1.2,'1_RAW_CORRELATIONS'!AF6*1.1,'1_RAW_CORRELATIONS'!AG6*1.2,'1_RAW_CORRELATIONS'!AH6*1,'1_RAW_CORRELATIONS'!AI6*1,'1_RAW_CORRELATIONS'!AJ6*1.1,'1_RAW_CORRELATIONS'!AK6*1.1,'1_RAW_CORRELATIONS'!AL6*0.9)-0 -> -0.045347072 | I6: =AVERAGE('1_RAW_CORRELATIONS'!AM6*1,'1_RAW_CORRELATIONS'!AN6*1.2,'1_RAW_CORRELATIONS'!AO6*1,'1_RAW_CORRELATIONS'!AP6*1.3,'1_RAW_CORRELATIONS'!AQ6*1.2,'1_RAW_CORRELATIONS'!AR6*1.3,'1_RAW_CORRELATIONS'!AS6*1.1,'1_RAW_CORRELATIONS'!AT6*0.7)-0 -> -0.14964641 | J6: =AVERAGE('1_RAW_CORRELATIONS'!AU6*1.2,'1_RAW_CORRELATIONS'!AV6*1.2,'1_RAW_CORRELATIONS'!AW6*1.3,'1_RAW_CORRELATIONS'!AX6*1)-0 -> -0.056550936 | K6: =AVERAGE('1_RAW_CORRELATIONS'!AY6*1.3,'1_RAW_CORRELATIONS'!AZ6*1.1,'1_RAW_CORRELATIONS'!BA6*1,'1_RAW_CORRELATIONS'!BB6*0.9,'1_RAW_CORRELATIONS'!BC6*1.2)-0 -> 0.01566644 | L6: =IFERROR((D6-AVERAGE(D$4:D$23))/STDEV(D$4:D$23),0) -> -1.6168679 | M6: =IFERROR((E6-AVERAGE(E$4:E$23))/STDEV(E$4:E$23),0) -> 1.0587552 | N6: =IFERROR((F6-AVERAGE(F$4:F$23))/STDEV(F$4:F$23),0) -> 0.55711834 | O6: =IFERROR((G6-AVERAGE(G$4:G$23))/STDEV(G$4:G$23),0) -> 0.33553973 | P6: =IFERROR((H6-AVERAGE(H$4:H$23))/STDEV(H$4:H$23),0) -> 1.4799903 | Q6: =IFERROR((I6-AVERAGE(I$4:I$23))/STDEV(I$4:I$23),0) -> -1.2025757 | R6: =IFERROR((J6-AVERAGE(J$4:J$23))/STDEV(J$4:J$23),0) -> -0.86890463 | S6: =IFERROR((K6-AVERAGE(K$4:K$23))/STDEV(K$4:K$23),0) -> 0.34007993
A7: ='1_RAW_CORRELATIONS'!A7 -> F04 | B7: ='1_RAW_CORRELATIONS'!B7 -> 4 | C7: =IF('2_FRAME_MARKUP'!E7=1,"HOOK ","" )&IF('2_FRAME_MARKUP'!F7=1,"BRAND ","" )&IF('2_FRAME_MARKUP'!G7=1,"PRODUCT ","" )&IF('2_FRAME_MARKUP'!H7=1,"OFFER ","" )&IF('2_FRAME_MARKUP'!I7=1,"CTA ","" )&IF('2_FRAME_MARKUP'!J7=1,"LOGO ","" ) -> LOGO | D7: =AVERAGE('1_RAW_CORRELATIONS'!E7*1,'1_RAW_CORRELATIONS'!F7*1.2,'1_RAW_CORRELATIONS'!G7*1,'1_RAW_CORRELATIONS'!H7*1.1,'1_RAW_CORRELATIONS'!I7*1,'1_RAW_CORRELATIONS'!J7*1.2,'1_RAW_CORRELATIONS'!K7*0.7)-(MAX(0,'1_RAW_CORRELATIONS'!L7)*1) -> 0.011867816 | E7: =AVERAGE('1_RAW_CORRELATIONS'!M7*1.3,'1_RAW_CORRELATIONS'!N7*1,'1_RAW_CORRELATIONS'!O7*0.5,'1_RAW_CORRELATIONS'!P7*0.6,'1_RAW_CORRELATIONS'!Q7*0.6)-0 -> -0.14073996 | F7: =AVERAGE('1_RAW_CORRELATIONS'!R7*1)-(MAX(0,'1_RAW_CORRELATIONS'!S7)*1.2+MAX(0,'1_RAW_CORRELATIONS'!T7)*1.5+MAX(0,'1_RAW_CORRELATIONS'!U7)*0.6+MAX(0,'1_RAW_CORRELATIONS'!V7)*0.5) -> -0.17218274 | G7: =AVERAGE('1_RAW_CORRELATIONS'!W7*1.5,'1_RAW_CORRELATIONS'!X7*1.3,'1_RAW_CORRELATIONS'!Y7*1,'1_RAW_CORRELATIONS'!Z7*1,'1_RAW_CORRELATIONS'!AA7*1.1,'1_RAW_CORRELATIONS'!AB7*1,'1_RAW_CORRELATIONS'!AC7*0.9)-0 -> 0.018876743 | H7: =AVERAGE('1_RAW_CORRELATIONS'!AD7*1,'1_RAW_CORRELATIONS'!AE7*1.2,'1_RAW_CORRELATIONS'!AF7*1.1,'1_RAW_CORRELATIONS'!AG7*1.2,'1_RAW_CORRELATIONS'!AH7*1,'1_RAW_CORRELATIONS'!AI7*1,'1_RAW_CORRELATIONS'!AJ7*1.1,'1_RAW_CORRELATIONS'!AK7*1.1,'1_RAW_CORRELATIONS'!AL7*0.9)-0 -> -0.064535488 | I7: =AVERAGE('1_RAW_CORRELATIONS'!AM7*1,'1_RAW_CORRELATIONS'!AN7*1.2,'1_RAW_CORRELATIONS'!AO7*1,'1_RAW_CORRELATIONS'!AP7*1.3,'1_RAW_CORRELATIONS'!AQ7*1.2,'1_RAW_CORRELATIONS'!AR7*1.3,'1_RAW_CORRELATIONS'!AS7*1.1,'1_RAW_CORRELATIONS'!AT7*0.7)-0 -> -0.11932253 | J7: =AVERAGE('1_RAW_CORRELATIONS'!AU7*1.2,'1_RAW_CORRELATIONS'!AV7*1.2,'1_RAW_CORRELATIONS'!AW7*1.3,'1_RAW_CORRELATIONS'!AX7*1)-0 -> -0.030187159 | K7: =AVERAGE('1_RAW_CORRELATIONS'!AY7*1.3,'1_RAW_CORRELATIONS'!AZ7*1.1,'1_RAW_CORRELATIONS'!BA7*1,'1_RAW_CORRELATIONS'!BB7*0.9,'1_RAW_CORRELATIONS'!BC7*1.2)-0 -> -0.0057778483 | L7: =IFERROR((D7-AVERAGE(D$4:D$23))/STDEV(D$4:D$23),0) -> -0.73232779 | M7: =IFERROR((E7-AVERAGE(E$4:E$23))/STDEV(E$4:E$23),0) -> 0.90619857 | N7: =IFERROR((F7-AVERAGE(F$4:F$23))/STDEV(F$4:F$23),0) -> 0.57936924 | O7: =IFERROR((G7-AVERAGE(G$4:G$23))/STDEV(G$4:G$23),0) -> 0.26085103 | P7: =IFERROR((H7-AVERAGE(H$4:H$23))/STDEV(H$4:H$23),0) -> 1.0243027 | Q7: =IFERROR((I7-AVERAGE(I$4:I$23))/STDEV(I$4:I$23),0) -> -0.74906485 | R7: =IFERROR((J7-AVERAGE(J$4:J$23))/STDEV(J$4:J$23),0) -> -0.51829645 | S7: =IFERROR((K7-AVERAGE(K$4:K$23))/STDEV(K$4:K$23),0) -> -0.14826525
A8: ='1_RAW_CORRELATIONS'!A8 -> F05 | B8: ='1_RAW_CORRELATIONS'!B8 -> 5 | C8: =IF('2_FRAME_MARKUP'!E8=1,"HOOK ","" )&IF('2_FRAME_MARKUP'!F8=1,"BRAND ","" )&IF('2_FRAME_MARKUP'!G8=1,"PRODUCT ","" )&IF('2_FRAME_MARKUP'!H8=1,"OFFER ","" )&IF('2_FRAME_MARKUP'!I8=1,"CTA ","" )&IF('2_FRAME_MARKUP'!J8=1,"LOGO ","" ) | D8: =AVERAGE('1_RAW_CORRELATIONS'!E8*1,'1_RAW_CORRELATIONS'!F8*1.2,'1_RAW_CORRELATIONS'!G8*1,'1_RAW_CORRELATIONS'!H8*1.1,'1_RAW_CORRELATIONS'!I8*1,'1_RAW_CORRELATIONS'!J8*1.2,'1_RAW_CORRELATIONS'!K8*0.7)-(MAX(0,'1_RAW_CORRELATIONS'!L8)*1) -> 0.023606919 | E8: =AVERAGE('1_RAW_CORRELATIONS'!M8*1.3,'1_RAW_CORRELATIONS'!N8*1,'1_RAW_CORRELATIONS'!O8*0.5,'1_RAW_CORRELATIONS'!P8*0.6,'1_RAW_CORRELATIONS'!Q8*0.6)-0 -> -0.14040853 | F8: =AVERAGE('1_RAW_CORRELATIONS'!R8*1)-(MAX(0,'1_RAW_CORRELATIONS'!S8)*1.2+MAX(0,'1_RAW_CORRELATIONS'!T8)*1.5+MAX(0,'1_RAW_CORRELATIONS'!U8)*0.6+MAX(0,'1_RAW_CORRELATIONS'!V8)*0.5) -> -0.18675592 | G8: =AVERAGE('1_RAW_CORRELATIONS'!W8*1.5,'1_RAW_CORRELATIONS'!X8*1.3,'1_RAW_CORRELATIONS'!Y8*1,'1_RAW_CORRELATIONS'!Z8*1,'1_RAW_CORRELATIONS'!AA8*1.1,'1_RAW_CORRELATIONS'!AB8*1,'1_RAW_CORRELATIONS'!AC8*0.9)-0 -> 0.020209709 | H8: =AVERAGE('1_RAW_CORRELATIONS'!AD8*1,'1_RAW_CORRELATIONS'!AE8*1.2,'1_RAW_CORRELATIONS'!AF8*1.1,'1_RAW_CORRELATIONS'!AG8*1.2,'1_RAW_CORRELATIONS'!AH8*1,'1_RAW_CORRELATIONS'!AI8*1,'1_RAW_CORRELATIONS'!AJ8*1.1,'1_RAW_CORRELATIONS'!AK8*1.1,'1_RAW_CORRELATIONS'!AL8*0.9)-0 -> -0.0599764 | I8: =AVERAGE('1_RAW_CORRELATIONS'!AM8*1,'1_RAW_CORRELATIONS'!AN8*1.2,'1_RAW_CORRELATIONS'!AO8*1,'1_RAW_CORRELATIONS'!AP8*1.3,'1_RAW_CORRELATIONS'!AQ8*1.2,'1_RAW_CORRELATIONS'!AR8*1.3,'1_RAW_CORRELATIONS'!AS8*1.1,'1_RAW_CORRELATIONS'!AT8*0.7)-0 -> -0.10953292 | J8: =AVERAGE('1_RAW_CORRELATIONS'!AU8*1.2,'1_RAW_CORRELATIONS'!AV8*1.2,'1_RAW_CORRELATIONS'!AW8*1.3,'1_RAW_CORRELATIONS'!AX8*1)-0 -> -0.055741392 | K8: =AVERAGE('1_RAW_CORRELATIONS'!AY8*1.3,'1_RAW_CORRELATIONS'!AZ8*1.1,'1_RAW_CORRELATIONS'!BA8*1,'1_RAW_CORRELATIONS'!BB8*0.9,'1_RAW_CORRELATIONS'!BC8*1.2)-0 -> -0.010869838 | L8: =IFERROR((D8-AVERAGE(D$4:D$23))/STDEV(D$4:D$23),0) -> 0.12341103 | M8: =IFERROR((E8-AVERAGE(E$4:E$23))/STDEV(E$4:E$23),0) -> 0.92129166 | N8: =IFERROR((F8-AVERAGE(F$4:F$23))/STDEV(F$4:F$23),0) -> 0.13674618 | O8: =IFERROR((G8-AVERAGE(G$4:G$23))/STDEV(G$4:G$23),0) -> 0.30269401 | P8: =IFERROR((H8-AVERAGE(H$4:H$23))/STDEV(H$4:H$23),0) -> 1.1325721 | Q8: =IFERROR((I8-AVERAGE(I$4:I$23))/STDEV(I$4:I$23),0) -> -0.60265569 | R8: =IFERROR((J8-AVERAGE(J$4:J$23))/STDEV(J$4:J$23),0) -> -0.85813862 | S8: =IFERROR((K8-AVERAGE(K$4:K$23))/STDEV(K$4:K$23),0) -> -0.2642238
A9: ='1_RAW_CORRELATIONS'!A9 -> F06 | B9: ='1_RAW_CORRELATIONS'!B9 -> 6 | C9: =IF('2_FRAME_MARKUP'!E9=1,"HOOK ","" )&IF('2_FRAME_MARKUP'!F9=1,"BRAND ","" )&IF('2_FRAME_MARKUP'!G9=1,"PRODUCT ","" )&IF('2_FRAME_MARKUP'!H9=1,"OFFER ","" )&IF('2_FRAME_MARKUP'!I9=1,"CTA ","" )&IF('2_FRAME_MARKUP'!J9=1,"LOGO ","" ) | D9: =AVERAGE('1_RAW_CORRELATIONS'!E9*1,'1_RAW_CORRELATIONS'!F9*1.2,'1_RAW_CORRELATIONS'!G9*1,'1_RAW_CORRELATIONS'!H9*1.1,'1_RAW_CORRELATIONS'!I9*1,'1_RAW_CORRELATIONS'!J9*1.2,'1_RAW_CORRELATIONS'!K9*0.7)-(MAX(0,'1_RAW_CORRELATIONS'!L9)*1) -> 0.026177482 | E9: =AVERAGE('1_RAW_CORRELATIONS'!M9*1.3,'1_RAW_CORRELATIONS'!N9*1,'1_RAW_CORRELATIONS'!O9*0.5,'1_RAW_CORRELATIONS'!P9*0.6,'1_RAW_CORRELATIONS'!Q9*0.6)-0 -> -0.15507293 | F9: =AVERAGE('1_RAW_CORRELATIONS'!R9*1)-(MAX(0,'1_RAW_CORRELATIONS'!S9)*1.2+MAX(0,'1_RAW_CORRELATIONS'!T9)*1.5+MAX(0,'1_RAW_CORRELATIONS'!U9)*0.6+MAX(0,'1_RAW_CORRELATIONS'!V9)*0.5) -> -0.19600896 | G9: =AVERAGE('1_RAW_CORRELATIONS'!W9*1.5,'1_RAW_CORRELATIONS'!X9*1.3,'1_RAW_CORRELATIONS'!Y9*1,'1_RAW_CORRELATIONS'!Z9*1,'1_RAW_CORRELATIONS'!AA9*1.1,'1_RAW_CORRELATIONS'!AB9*1,'1_RAW_CORRELATIONS'!AC9*0.9)-0 -> 0.0054538035 | H9: =AVERAGE('1_RAW_CORRELATIONS'!AD9*1,'1_RAW_CORRELATIONS'!AE9*1.2,'1_RAW_CORRELATIONS'!AF9*1.1,'1_RAW_CORRELATIONS'!AG9*1.2,'1_RAW_CORRELATIONS'!AH9*1,'1_RAW_CORRELATIONS'!AI9*1,'1_RAW_CORRELATIONS'!AJ9*1.1,'1_RAW_CORRELATIONS'!AK9*1.1,'1_RAW_CORRELATIONS'!AL9*0.9)-0 -> -0.083133238 | I9: =AVERAGE('1_RAW_CORRELATIONS'!AM9*1,'1_RAW_CORRELATIONS'!AN9*1.2,'1_RAW_CORRELATIONS'!AO9*1,'1_RAW_CORRELATIONS'!AP9*1.3,'1_RAW_CORRELATIONS'!AQ9*1.2,'1_RAW_CORRELATIONS'!AR9*1.3,'1_RAW_CORRELATIONS'!AS9*1.1,'1_RAW_CORRELATIONS'!AT9*0.7)-0 -> -0.10525744 | J9: =AVERAGE('1_RAW_CORRELATIONS'!AU9*1.2,'1_RAW_CORRELATIONS'!AV9*1.2,'1_RAW_CORRELATIONS'!AW9*1.3,'1_RAW_CORRELATIONS'!AX9*1)-0 -> -0.039087682 | K9: =AVERAGE('1_RAW_CORRELATIONS'!AY9*1.3,'1_RAW_CORRELATIONS'!AZ9*1.1,'1_RAW_CORRELATIONS'!BA9*1,'1_RAW_CORRELATIONS'!BB9*0.9,'1_RAW_CORRELATIONS'!BC9*1.2)-0 -> -0.011554935 | L9: =IFERROR((D9-AVERAGE(D$4:D$23))/STDEV(D$4:D$23),0) -> 0.31079594 | M9: =IFERROR((E9-AVERAGE(E$4:E$23))/STDEV(E$4:E$23),0) -> 0.25348139 | N9: =IFERROR((F9-AVERAGE(F$4:F$23))/STDEV(F$4:F$23),0) -> -0.14429135 | O9: =IFERROR((G9-AVERAGE(G$4:G$23))/STDEV(G$4:G$23),0) -> -0.160507 | P9: =IFERROR((H9-AVERAGE(H$4:H$23))/STDEV(H$4:H$23),0) -> 0.58264223 | Q9: =IFERROR((I9-AVERAGE(I$4:I$23))/STDEV(I$4:I$23),0) -> -0.53871345 | R9: =IFERROR((J9-AVERAGE(J$4:J$23))/STDEV(J$4:J$23),0) -> -0.63666326 | S9: =IFERROR((K9-AVERAGE(K$4:K$23))/STDEV(K$4:K$23),0) -> -0.27982534
A10: ='1_RAW_CORRELATIONS'!A10 -> F07 | B10: ='1_RAW_CORRELATIONS'!B10 -> 7 | C10: =IF('2_FRAME_MARKUP'!E10=1,"HOOK ","" )&IF('2_FRAME_MARKUP'!F10=1,"BRAND ","" )&IF('2_FRAME_MARKUP'!G10=1,"PRODUCT ","" )&IF('2_FRAME_MARKUP'!H10=1,"OFFER ","" )&IF('2_FRAME_MARKUP'!I10=1,"CTA ","" )&IF('2_FRAME_MARKUP'!J10=1,"LOGO ","" ) | D10: =AVERAGE('1_RAW_CORRELATIONS'!E10*1,'1_RAW_CORRELATIONS'!F10*1.2,'1_RAW_CORRELATIONS'!G10*1,'1_RAW_CORRELATIONS'!H10*1.1,'1_RAW_CORRELATIONS'!I10*1,'1_RAW_CORRELATIONS'!J10*1.2,'1_RAW_CORRELATIONS'!K10*0.7)-(MAX(0,'1_RAW_CORRELATIONS'!L10)*1) -> 0.027360771 | E10: =AVERAGE('1_RAW_CORRELATIONS'!M10*1.3,'1_RAW_CORRELATIONS'!N10*1,'1_RAW_CORRELATIONS'!O10*0.5,'1_RAW_CORRELATIONS'!P10*0.6,'1_RAW_CORRELATIONS'!Q10*0.6)-0 -> -0.16246203 | F10: =AVERAGE('1_RAW_CORRELATIONS'!R10*1)-(MAX(0,'1_RAW_CORRELATIONS'!S10)*1.2+MAX(0,'1_RAW_CORRELATIONS'!T10)*1.5+MAX(0,'1_RAW_CORRELATIONS'!U10)*0.6+MAX(0,'1_RAW_CORRELATIONS'!V10)*0.5) -> -0.19366259 | G10: =AVERAGE('1_RAW_CORRELATIONS'!W10*1.5,'1_RAW_CORRELATIONS'!X10*1.3,'1_RAW_CORRELATIONS'!Y10*1,'1_RAW_CORRELATIONS'!Z10*1,'1_RAW_CORRELATIONS'!AA10*1.1,'1_RAW_CORRELATIONS'!AB10*1,'1_RAW_CORRELATIONS'!AC10*0.9)-0 -> 0.0017717976 | H10: =AVERAGE('1_RAW_CORRELATIONS'!AD10*1,'1_RAW_CORRELATIONS'!AE10*1.2,'1_RAW_CORRELATIONS'!AF10*1.1,'1_RAW_CORRELATIONS'!AG10*1.2,'1_RAW_CORRELATIONS'!AH10*1,'1_RAW_CORRELATIONS'!AI10*1,'1_RAW_CORRELATIONS'!AJ10*1.1,'1_RAW_CORRELATIONS'!AK10*1.1,'1_RAW_CORRELATIONS'!AL10*0.9)-0 -> -0.098186013 | I10: =AVERAGE('1_RAW_CORRELATIONS'!AM10*1,'1_RAW_CORRELATIONS'!AN10*1.2,'1_RAW_CORRELATIONS'!AO10*1,'1_RAW_CORRELATIONS'!AP10*1.3,'1_RAW_CORRELATIONS'!AQ10*1.2,'1_RAW_CORRELATIONS'!AR10*1.3,'1_RAW_CORRELATIONS'!AS10*1.1,'1_RAW_CORRELATIONS'!AT10*0.7)-0 -> -0.099784824 | J10: =AVERAGE('1_RAW_CORRELATIONS'!AU10*1.2,'1_RAW_CORRELATIONS'!AV10*1.2,'1_RAW_CORRELATIONS'!AW10*1.3,'1_RAW_CORRELATIONS'!AX10*1)-0 -> -0.0055599106 | K10: =AVERAGE('1_RAW_CORRELATIONS'!AY10*1.3,'1_RAW_CORRELATIONS'!AZ10*1.1,'1_RAW_CORRELATIONS'!BA10*1,'1_RAW_CORRELATIONS'!BB10*0.9,'1_RAW_CORRELATIONS'!BC10*1.2)-0 -> -0.01340343 | L10: =IFERROR((D10-AVERAGE(D$4:D$23))/STDEV(D$4:D$23),0) -> 0.3970535 | M10: =IFERROR((E10-AVERAGE(E$4:E$23))/STDEV(E$4:E$23),0) -> -0.083015214 | N10: =IFERROR((F10-AVERAGE(F$4:F$23))/STDEV(F$4:F$23),0) -> -0.073026485 | O10: =IFERROR((G10-AVERAGE(G$4:G$23))/STDEV(G$4:G$23),0) -> -0.27608845 | P10: =IFERROR((H10-AVERAGE(H$4:H$23))/STDEV(H$4:H$23),0) -> 0.22516808 | Q10: =IFERROR((I10-AVERAGE(I$4:I$23))/STDEV(I$4:I$23),0) -> -0.45686734 | R10: =IFERROR((J10-AVERAGE(J$4:J$23))/STDEV(J$4:J$23),0) -> -0.19078212 | S10: =IFERROR((K10-AVERAGE(K$4:K$23))/STDEV(K$4:K$23),0) -> -0.32192063
A11: ='1_RAW_CORRELATIONS'!A11 -> F08 | B11: ='1_RAW_CORRELATIONS'!B11 -> 8 | C11: =IF('2_FRAME_MARKUP'!E11=1,"HOOK ","" )&IF('2_FRAME_MARKUP'!F11=1,"BRAND ","" )&IF('2_FRAME_MARKUP'!G11=1,"PRODUCT ","" )&IF('2_FRAME_MARKUP'!H11=1,"OFFER ","" )&IF('2_FRAME_MARKUP'!I11=1,"CTA ","" )&IF('2_FRAME_MARKUP'!J11=1,"LOGO ","" ) | D11: =AVERAGE('1_RAW_CORRELATIONS'!E11*1,'1_RAW_CORRELATIONS'!F11*1.2,'1_RAW_CORRELATIONS'!G11*1,'1_RAW_CORRELATIONS'!H11*1.1,'1_RAW_CORRELATIONS'!I11*1,'1_RAW_CORRELATIONS'!J11*1.2,'1_RAW_CORRELATIONS'!K11*0.7)-(MAX(0,'1_RAW_CORRELATIONS'!L11)*1) -> 0.026765881 | E11: =AVERAGE('1_RAW_CORRELATIONS'!M11*1.3,'1_RAW_CORRELATIONS'!N11*1,'1_RAW_CORRELATIONS'!O11*0.5,'1_RAW_CORRELATIONS'!P11*0.6,'1_RAW_CORRELATIONS'!Q11*0.6)-0 -> -0.16837066 | F11: =AVERAGE('1_RAW_CORRELATIONS'!R11*1)-(MAX(0,'1_RAW_CORRELATIONS'!S11)*1.2+MAX(0,'1_RAW_CORRELATIONS'!T11)*1.5+MAX(0,'1_RAW_CORRELATIONS'!U11)*0.6+MAX(0,'1_RAW_CORRELATIONS'!V11)*0.5) -> -0.19666857 | G11: =AVERAGE('1_RAW_CORRELATIONS'!W11*1.5,'1_RAW_CORRELATIONS'!X11*1.3,'1_RAW_CORRELATIONS'!Y11*1,'1_RAW_CORRELATIONS'!Z11*1,'1_RAW_CORRELATIONS'!AA11*1.1,'1_RAW_CORRELATIONS'!AB11*1,'1_RAW_CORRELATIONS'!AC11*0.9)-0 -> 0.0095719943 | H11: =AVERAGE('1_RAW_CORRELATIONS'!AD11*1,'1_RAW_CORRELATIONS'!AE11*1.2,'1_RAW_CORRELATIONS'!AF11*1.1,'1_RAW_CORRELATIONS'!AG11*1.2,'1_RAW_CORRELATIONS'!AH11*1,'1_RAW_CORRELATIONS'!AI11*1,'1_RAW_CORRELATIONS'!AJ11*1.1,'1_RAW_CORRELATIONS'!AK11*1.1,'1_RAW_CORRELATIONS'!AL11*0.9)-0 -> -0.11340121 | I11: =AVERAGE('1_RAW_CORRELATIONS'!AM11*1,'1_RAW_CORRELATIONS'!AN11*1.2,'1_RAW_CORRELATIONS'!AO11*1,'1_RAW_CORRELATIONS'!AP11*1.3,'1_RAW_CORRELATIONS'!AQ11*1.2,'1_RAW_CORRELATIONS'!AR11*1.3,'1_RAW_CORRELATIONS'!AS11*1.1,'1_RAW_CORRELATIONS'!AT11*0.7)-0 -> -0.078964599 | J11: =AVERAGE('1_RAW_CORRELATIONS'!AU11*1.2,'1_RAW_CORRELATIONS'!AV11*1.2,'1_RAW_CORRELATIONS'!AW11*1.3,'1_RAW_CORRELATIONS'!AX11*1)-0 -> 0.022974384 | K11: =AVERAGE('1_RAW_CORRELATIONS'!AY11*1.3,'1_RAW_CORRELATIONS'!AZ11*1.1,'1_RAW_CORRELATIONS'!BA11*1,'1_RAW_CORRELATIONS'!BB11*0.9,'1_RAW_CORRELATIONS'!BC11*1.2)-0 -> -0.022950546 | L11: =IFERROR((D11-AVERAGE(D$4:D$23))/STDEV(D$4:D$23),0) -> 0.3536881 | M11: =IFERROR((E11-AVERAGE(E$4:E$23))/STDEV(E$4:E$23),0) -> -0.35209179 | N11: =IFERROR((F11-AVERAGE(F$4:F$23))/STDEV(F$4:F$23),0) -> -0.16432521 | O11: =IFERROR((G11-AVERAGE(G$4:G$23))/STDEV(G$4:G$23),0) -> -0.031233328 | P11: =IFERROR((H11-AVERAGE(H$4:H$23))/STDEV(H$4:H$23),0) -> -0.13616326 | Q11: =IFERROR((I11-AVERAGE(I$4:I$23))/STDEV(I$4:I$23),0) -> -0.14548905 | R11: =IFERROR((J11-AVERAGE(J$4:J$23))/STDEV(J$4:J$23),0) -> 0.18869147 | S11: =IFERROR((K11-AVERAGE(K$4:K$23))/STDEV(K$4:K$23),0) -> -0.53933461
A12: ='1_RAW_CORRELATIONS'!A12 -> F09 | B12: ='1_RAW_CORRELATIONS'!B12 -> 9 | C12: =IF('2_FRAME_MARKUP'!E12=1,"HOOK ","" )&IF('2_FRAME_MARKUP'!F12=1,"BRAND ","" )&IF('2_FRAME_MARKUP'!G12=1,"PRODUCT ","" )&IF('2_FRAME_MARKUP'!H12=1,"OFFER ","" )&IF('2_FRAME_MARKUP'!I12=1,"CTA ","" )&IF('2_FRAME_MARKUP'!J12=1,"LOGO ","" ) | D12: =AVERAGE('1_RAW_CORRELATIONS'!E12*1,'1_RAW_CORRELATIONS'!F12*1.2,'1_RAW_CORRELATIONS'!G12*1,'1_RAW_CORRELATIONS'!H12*1.1,'1_RAW_CORRELATIONS'!I12*1,'1_RAW_CORRELATIONS'!J12*1.2,'1_RAW_CORRELATIONS'!K12*0.7)-(MAX(0,'1_RAW_CORRELATIONS'!L12)*1) -> 0.022624659 | E12: =AVERAGE('1_RAW_CORRELATIONS'!M12*1.3,'1_RAW_CORRELATIONS'!N12*1,'1_RAW_CORRELATIONS'!O12*0.5,'1_RAW_CORRELATIONS'!P12*0.6,'1_RAW_CORRELATIONS'!Q12*0.6)-0 -> -0.16396503 | F12: =AVERAGE('1_RAW_CORRELATIONS'!R12*1)-(MAX(0,'1_RAW_CORRELATIONS'!S12)*1.2+MAX(0,'1_RAW_CORRELATIONS'!T12)*1.5+MAX(0,'1_RAW_CORRELATIONS'!U12)*0.6+MAX(0,'1_RAW_CORRELATIONS'!V12)*0.5) -> -0.18299971 | G12: =AVERAGE('1_RAW_CORRELATIONS'!W12*1.5,'1_RAW_CORRELATIONS'!X12*1.3,'1_RAW_CORRELATIONS'!Y12*1,'1_RAW_CORRELATIONS'!Z12*1,'1_RAW_CORRELATIONS'!AA12*1.1,'1_RAW_CORRELATIONS'!AB12*1,'1_RAW_CORRELATIONS'!AC12*0.9)-0 -> 0.018985336 | H12: =AVERAGE('1_RAW_CORRELATIONS'!AD12*1,'1_RAW_CORRELATIONS'!AE12*1.2,'1_RAW_CORRELATIONS'!AF12*1.1,'1_RAW_CORRELATIONS'!AG12*1.2,'1_RAW_CORRELATIONS'!AH12*1,'1_RAW_CORRELATIONS'!AI12*1,'1_RAW_CORRELATIONS'!AJ12*1.1,'1_RAW_CORRELATIONS'!AK12*1.1,'1_RAW_CORRELATIONS'!AL12*0.9)-0 -> -0.12026863 | I12: =AVERAGE('1_RAW_CORRELATIONS'!AM12*1,'1_RAW_CORRELATIONS'!AN12*1.2,'1_RAW_CORRELATIONS'!AO12*1,'1_RAW_CORRELATIONS'!AP12*1.3,'1_RAW_CORRELATIONS'!AQ12*1.2,'1_RAW_CORRELATIONS'!AR12*1.3,'1_RAW_CORRELATIONS'!AS12*1.1,'1_RAW_CORRELATIONS'!AT12*0.7)-0 -> -0.063470591 | J12: =AVERAGE('1_RAW_CORRELATIONS'!AU12*1.2,'1_RAW_CORRELATIONS'!AV12*1.2,'1_RAW_CORRELATIONS'!AW12*1.3,'1_RAW_CORRELATIONS'!AX12*1)-0 -> 0.087414324 | K12: =AVERAGE('1_RAW_CORRELATIONS'!AY12*1.3,'1_RAW_CORRELATIONS'!AZ12*1.1,'1_RAW_CORRELATIONS'!BA12*1,'1_RAW_CORRELATIONS'!BB12*0.9,'1_RAW_CORRELATIONS'!BC12*1.2)-0 -> -0.039440383 | L12: =IFERROR((D12-AVERAGE(D$4:D$23))/STDEV(D$4:D$23),0) -> 0.051807769 | M12: =IFERROR((E12-AVERAGE(E$4:E$23))/STDEV(E$4:E$23),0) -> -0.1514614 | N12: =IFERROR((F12-AVERAGE(F$4:F$23))/STDEV(F$4:F$23),0) -> 0.25083135 | O12: =IFERROR((G12-AVERAGE(G$4:G$23))/STDEV(G$4:G$23),0) -> 0.26425985 | P12: =IFERROR((H12-AVERAGE(H$4:H$23))/STDEV(H$4:H$23),0) -> -0.29925108 | Q12: =IFERROR((I12-AVERAGE(I$4:I$23))/STDEV(I$4:I$23),0) -> 0.086232633 | R12: =IFERROR((J12-AVERAGE(J$4:J$23))/STDEV(J$4:J$23),0) -> 1.0456692 | S12: =IFERROR((K12-AVERAGE(K$4:K$23))/STDEV(K$4:K$23),0) -> -0.91485336
A13: ='1_RAW_CORRELATIONS'!A13 -> F10 | B13: ='1_RAW_CORRELATIONS'!B13 -> 10 | C13: =IF('2_FRAME_MARKUP'!E13=1,"HOOK ","" )&IF('2_FRAME_MARKUP'!F13=1,"BRAND ","" )&IF('2_FRAME_MARKUP'!G13=1,"PRODUCT ","" )&IF('2_FRAME_MARKUP'!H13=1,"OFFER ","" )&IF('2_FRAME_MARKUP'!I13=1,"CTA ","" )&IF('2_FRAME_MARKUP'!J13=1,"LOGO ","" ) | D13: =AVERAGE('1_RAW_CORRELATIONS'!E13*1,'1_RAW_CORRELATIONS'!F13*1.2,'1_RAW_CORRELATIONS'!G13*1,'1_RAW_CORRELATIONS'!H13*1.1,'1_RAW_CORRELATIONS'!I13*1,'1_RAW_CORRELATIONS'!J13*1.2,'1_RAW_CORRELATIONS'!K13*0.7)-(MAX(0,'1_RAW_CORRELATIONS'!L13)*1) -> 0.017533733 | E13: =AVERAGE('1_RAW_CORRELATIONS'!M13*1.3,'1_RAW_CORRELATIONS'!N13*1,'1_RAW_CORRELATIONS'!O13*0.5,'1_RAW_CORRELATIONS'!P13*0.6,'1_RAW_CORRELATIONS'!Q13*0.6)-0 -> -0.16017134 | F13: =AVERAGE('1_RAW_CORRELATIONS'!R13*1)-(MAX(0,'1_RAW_CORRELATIONS'!S13)*1.2+MAX(0,'1_RAW_CORRELATIONS'!T13)*1.5+MAX(0,'1_RAW_CORRELATIONS'!U13)*0.6+MAX(0,'1_RAW_CORRELATIONS'!V13)*0.5) -> -0.16936319 | G13: =AVERAGE('1_RAW_CORRELATIONS'!W13*1.5,'1_RAW_CORRELATIONS'!X13*1.3,'1_RAW_CORRELATIONS'!Y13*1,'1_RAW_CORRELATIONS'!Z13*1,'1_RAW_CORRELATIONS'!AA13*1.1,'1_RAW_CORRELATIONS'!AB13*1,'1_RAW_CORRELATIONS'!AC13*0.9)-0 -> 0.031329706 | H13: =AVERAGE('1_RAW_CORRELATIONS'!AD13*1,'1_RAW_CORRELATIONS'!AE13*1.2,'1_RAW_CORRELATIONS'!AF13*1.1,'1_RAW_CORRELATIONS'!AG13*1.2,'1_RAW_CORRELATIONS'!AH13*1,'1_RAW_CORRELATIONS'!AI13*1,'1_RAW_CORRELATIONS'!AJ13*1.1,'1_RAW_CORRELATIONS'!AK13*1.1,'1_RAW_CORRELATIONS'!AL13*0.9)-0 -> -0.13073221 | I13: =AVERAGE('1_RAW_CORRELATIONS'!AM13*1,'1_RAW_CORRELATIONS'!AN13*1.2,'1_RAW_CORRELATIONS'!AO13*1,'1_RAW_CORRELATIONS'!AP13*1.3,'1_RAW_CORRELATIONS'!AQ13*1.2,'1_RAW_CORRELATIONS'!AR13*1.3,'1_RAW_CORRELATIONS'!AS13*1.1,'1_RAW_CORRELATIONS'!AT13*0.7)-0 -> -0.037672087 | J13: =AVERAGE('1_RAW_CORRELATIONS'!AU13*1.2,'1_RAW_CORRELATIONS'!AV13*1.2,'1_RAW_CORRELATIONS'!AW13*1.3,'1_RAW_CORRELATIONS'!AX13*1)-0 -> 0.13120285 | K13: =AVERAGE('1_RAW_CORRELATIONS'!AY13*1.3,'1_RAW_CORRELATIONS'!AZ13*1.1,'1_RAW_CORRELATIONS'!BA13*1,'1_RAW_CORRELATIONS'!BB13*0.9,'1_RAW_CORRELATIONS'!BC13*1.2)-0 -> -0.047820327 | L13: =IFERROR((D13-AVERAGE(D$4:D$23))/STDEV(D$4:D$23),0) -> -0.31930262 | M13: =IFERROR((E13-AVERAGE(E$4:E$23))/STDEV(E$4:E$23),0) -> 0.02130178 | N13: =IFERROR((F13-AVERAGE(F$4:F$23))/STDEV(F$4:F$23),0) -> 0.66500587 | O13: =IFERROR((G13-AVERAGE(G$4:G$23))/STDEV(G$4:G$23),0) -> 0.65176061 | P13: =IFERROR((H13-AVERAGE(H$4:H$23))/STDEV(H$4:H$23),0) -> -0.5477409 | Q13: =IFERROR((I13-AVERAGE(I$4:I$23))/STDEV(I$4:I$23),0) -> 0.4720639 | R13: =IFERROR((J13-AVERAGE(J$4:J$23))/STDEV(J$4:J$23),0) -> 1.6280066 | S13: =IFERROR((K13-AVERAGE(K$4:K$23))/STDEV(K$4:K$23),0) -> -1.1056876
A14: ='1_RAW_CORRELATIONS'!A14 -> F11 | B14: ='1_RAW_CORRELATIONS'!B14 -> 11 | C14: =IF('2_FRAME_MARKUP'!E14=1,"HOOK ","" )&IF('2_FRAME_MARKUP'!F14=1,"BRAND ","" )&IF('2_FRAME_MARKUP'!G14=1,"PRODUCT ","" )&IF('2_FRAME_MARKUP'!H14=1,"OFFER ","" )&IF('2_FRAME_MARKUP'!I14=1,"CTA ","" )&IF('2_FRAME_MARKUP'!J14=1,"LOGO ","" ) | D14: =AVERAGE('1_RAW_CORRELATIONS'!E14*1,'1_RAW_CORRELATIONS'!F14*1.2,'1_RAW_CORRELATIONS'!G14*1,'1_RAW_CORRELATIONS'!H14*1.1,'1_RAW_CORRELATIONS'!I14*1,'1_RAW_CORRELATIONS'!J14*1.2,'1_RAW_CORRELATIONS'!K14*0.7)-(MAX(0,'1_RAW_CORRELATIONS'!L14)*1) -> 0.021187669 | E14: =AVERAGE('1_RAW_CORRELATIONS'!M14*1.3,'1_RAW_CORRELATIONS'!N14*1,'1_RAW_CORRELATIONS'!O14*0.5,'1_RAW_CORRELATIONS'!P14*0.6,'1_RAW_CORRELATIONS'!Q14*0.6)-0 -> -0.15607655 | F14: =AVERAGE('1_RAW_CORRELATIONS'!R14*1)-(MAX(0,'1_RAW_CORRELATIONS'!S14)*1.2+MAX(0,'1_RAW_CORRELATIONS'!T14)*1.5+MAX(0,'1_RAW_CORRELATIONS'!U14)*0.6+MAX(0,'1_RAW_CORRELATIONS'!V14)*0.5) -> -0.1604868 | G14: =AVERAGE('1_RAW_CORRELATIONS'!W14*1.5,'1_RAW_CORRELATIONS'!X14*1.3,'1_RAW_CORRELATIONS'!Y14*1,'1_RAW_CORRELATIONS'!Z14*1,'1_RAW_CORRELATIONS'!AA14*1.1,'1_RAW_CORRELATIONS'!AB14*1,'1_RAW_CORRELATIONS'!AC14*0.9)-0 -> 0.037378213 | H14: =AVERAGE('1_RAW_CORRELATIONS'!AD14*1,'1_RAW_CORRELATIONS'!AE14*1.2,'1_RAW_CORRELATIONS'!AF14*1.1,'1_RAW_CORRELATIONS'!AG14*1.2,'1_RAW_CORRELATIONS'!AH14*1,'1_RAW_CORRELATIONS'!AI14*1,'1_RAW_CORRELATIONS'!AJ14*1.1,'1_RAW_CORRELATIONS'!AK14*1.1,'1_RAW_CORRELATIONS'!AL14*0.9)-0 -> -0.13743722 | I14: =AVERAGE('1_RAW_CORRELATIONS'!AM14*1,'1_RAW_CORRELATIONS'!AN14*1.2,'1_RAW_CORRELATIONS'!AO14*1,'1_RAW_CORRELATIONS'!AP14*1.3,'1_RAW_CORRELATIONS'!AQ14*1.2,'1_RAW_CORRELATIONS'!AR14*1.3,'1_RAW_CORRELATIONS'!AS14*1.1,'1_RAW_CORRELATIONS'!AT14*0.7)-0 -> -0.007726189 | J14: =AVERAGE('1_RAW_CORRELATIONS'!AU14*1.2,'1_RAW_CORRELATIONS'!AV14*1.2,'1_RAW_CORRELATIONS'!AW14*1.3,'1_RAW_CORRELATIONS'!AX14*1)-0 -> 0.13757824 | K14: =AVERAGE('1_RAW_CORRELATIONS'!AY14*1.3,'1_RAW_CORRELATIONS'!AZ14*1.1,'1_RAW_CORRELATIONS'!BA14*1,'1_RAW_CORRELATIONS'!BB14*0.9,'1_RAW_CORRELATIONS'!BC14*1.2)-0 -> -0.043499109 | L14: =IFERROR((D14-AVERAGE(D$4:D$23))/STDEV(D$4:D$23),0) -> -0.052943698 | M14: =IFERROR((E14-AVERAGE(E$4:E$23))/STDEV(E$4:E$23),0) -> 0.20777686 | N14: =IFERROR((F14-AVERAGE(F$4:F$23))/STDEV(F$4:F$23),0) -> 0.93460333 | O14: =IFERROR((G14-AVERAGE(G$4:G$23))/STDEV(G$4:G$23),0) -> 0.84162864 | P14: =IFERROR((H14-AVERAGE(H$4:H$23))/STDEV(H$4:H$23),0) -> -0.7069718 | Q14: =IFERROR((I14-AVERAGE(I$4:I$23))/STDEV(I$4:I$23),0) -> 0.9199218 | R14: =IFERROR((J14-AVERAGE(J$4:J$23))/STDEV(J$4:J$23),0) -> 1.7127922 | S14: =IFERROR((K14-AVERAGE(K$4:K$23))/STDEV(K$4:K$23),0) -> -1.0072817
A15: ='1_RAW_CORRELATIONS'!A15 -> F12 | B15: ='1_RAW_CORRELATIONS'!B15 -> 12 | C15: =IF('2_FRAME_MARKUP'!E15=1,"HOOK ","" )&IF('2_FRAME_MARKUP'!F15=1,"BRAND ","" )&IF('2_FRAME_MARKUP'!G15=1,"PRODUCT ","" )&IF('2_FRAME_MARKUP'!H15=1,"OFFER ","" )&IF('2_FRAME_MARKUP'!I15=1,"CTA ","" )&IF('2_FRAME_MARKUP'!J15=1,"LOGO ","" ) | D15: =AVERAGE('1_RAW_CORRELATIONS'!E15*1,'1_RAW_CORRELATIONS'!F15*1.2,'1_RAW_CORRELATIONS'!G15*1,'1_RAW_CORRELATIONS'!H15*1.1,'1_RAW_CORRELATIONS'!I15*1,'1_RAW_CORRELATIONS'!J15*1.2,'1_RAW_CORRELATIONS'!K15*0.7)-(MAX(0,'1_RAW_CORRELATIONS'!L15)*1) -> 0.022886907 | E15: =AVERAGE('1_RAW_CORRELATIONS'!M15*1.3,'1_RAW_CORRELATIONS'!N15*1,'1_RAW_CORRELATIONS'!O15*0.5,'1_RAW_CORRELATIONS'!P15*0.6,'1_RAW_CORRELATIONS'!Q15*0.6)-0 -> -0.15258871 | F15: =AVERAGE('1_RAW_CORRELATIONS'!R15*1)-(MAX(0,'1_RAW_CORRELATIONS'!S15)*1.2+MAX(0,'1_RAW_CORRELATIONS'!T15)*1.5+MAX(0,'1_RAW_CORRELATIONS'!U15)*0.6+MAX(0,'1_RAW_CORRELATIONS'!V15)*0.5) -> -0.15694939 | G15: =AVERAGE('1_RAW_CORRELATIONS'!W15*1.5,'1_RAW_CORRELATIONS'!X15*1.3,'1_RAW_CORRELATIONS'!Y15*1,'1_RAW_CORRELATIONS'!Z15*1,'1_RAW_CORRELATIONS'!AA15*1.1,'1_RAW_CORRELATIONS'!AB15*1,'1_RAW_CORRELATIONS'!AC15*0.9)-0 -> 0.038077008 | H15: =AVERAGE('1_RAW_CORRELATIONS'!AD15*1,'1_RAW_CORRELATIONS'!AE15*1.2,'1_RAW_CORRELATIONS'!AF15*1.1,'1_RAW_CORRELATIONS'!AG15*1.2,'1_RAW_CORRELATIONS'!AH15*1,'1_RAW_CORRELATIONS'!AI15*1,'1_RAW_CORRELATIONS'!AJ15*1.1,'1_RAW_CORRELATIONS'!AK15*1.1,'1_RAW_CORRELATIONS'!AL15*0.9)-0 -> -0.14114989 | I15: =AVERAGE('1_RAW_CORRELATIONS'!AM15*1,'1_RAW_CORRELATIONS'!AN15*1.2,'1_RAW_CORRELATIONS'!AO15*1,'1_RAW_CORRELATIONS'!AP15*1.3,'1_RAW_CORRELATIONS'!AQ15*1.2,'1_RAW_CORRELATIONS'!AR15*1.3,'1_RAW_CORRELATIONS'!AS15*1.1,'1_RAW_CORRELATIONS'!AT15*0.7)-0 -> 0.0064596557 | J15: =AVERAGE('1_RAW_CORRELATIONS'!AU15*1.2,'1_RAW_CORRELATIONS'!AV15*1.2,'1_RAW_CORRELATIONS'!AW15*1.3,'1_RAW_CORRELATIONS'!AX15*1)-0 -> 0.13302321 | K15: =AVERAGE('1_RAW_CORRELATIONS'!AY15*1.3,'1_RAW_CORRELATIONS'!AZ15*1.1,'1_RAW_CORRELATIONS'!BA15*1,'1_RAW_CORRELATIONS'!BB15*0.9,'1_RAW_CORRELATIONS'!BC15*1.2)-0 -> -0.058421759 | L15: =IFERROR((D15-AVERAGE(D$4:D$23))/STDEV(D$4:D$23),0) -> 0.070924751 | M15: =IFERROR((E15-AVERAGE(E$4:E$23))/STDEV(E$4:E$23),0) -> 0.36661129 | N15: =IFERROR((F15-AVERAGE(F$4:F$23))/STDEV(F$4:F$23),0) -> 1.0420433 | O15: =IFERROR((G15-AVERAGE(G$4:G$23))/STDEV(G$4:G$23),0) -> 0.86356441 | P15: =IFERROR((H15-AVERAGE(H$4:H$23))/STDEV(H$4:H$23),0) -> -0.79514061 | Q15: =IFERROR((I15-AVERAGE(I$4:I$23))/STDEV(I$4:I$23),0) -> 1.1320792 | R15: =IFERROR((J15-AVERAGE(J$4:J$23))/STDEV(J$4:J$23),0) -> 1.6522154 | S15: =IFERROR((K15-AVERAGE(K$4:K$23))/STDEV(K$4:K$23),0) -> -1.3471113
... A23: ='1_RAW_CORRELATIONS'!A23 -> F20 | B23: ='1_RAW_CORRELATIONS'!B23 -> 20 | C23: =IF('2_FRAME_MARKUP'!E23=1,"HOOK ","" )&IF('2_FRAME_MARKUP'!F23=1,"BRAND ","" )&IF('2_FRAME_MARKUP'!G23=1,"PRODUCT ","" )&IF('2_FRAME_MARKUP'!H23=1,"OFFER ","" )&IF('2_FRAME_MARKUP'!I23=1,"CTA ","" )&IF('2_FRAME_MARKUP'!J23=1,"LOGO ","" ) | D23: =AVERAGE('1_RAW_CORRELATIONS'!E23*1,'1_RAW_CORRELATIONS'!F23*1.2,'1_RAW_CORRELATIONS'!G23*1,'1_RAW_CORRELATIONS'!H23*1.1,'1_RAW_CORRELATIONS'!I23*1,'1_RAW_CORRELATIONS'!J23*1.2,'1_RAW_CORRELATIONS'!K23*0.7)-(MAX(0,'1_RAW_CORRELATIONS'!L23)*1) -> 0.010399157 | E23: =AVERAGE('1_RAW_CORRELATIONS'!M23*1.3,'1_RAW_CORRELATIONS'!N23*1,'1_RAW_CORRELATIONS'!O23*0.5,'1_RAW_CORRELATIONS'!P23*0.6,'1_RAW_CORRELATIONS'!Q23*0.6)-0 -> -0.2289053 | F23: =AVERAGE('1_RAW_CORRELATIONS'!R23*1)-(MAX(0,'1_RAW_CORRELATIONS'!S23)*1.2+MAX(0,'1_RAW_CORRELATIONS'!T23)*1.5+MAX(0,'1_RAW_CORRELATIONS'!U23)*0.6+MAX(0,'1_RAW_CORRELATIONS'!V23)*0.5) -> -0.30241502 | G23: =AVERAGE('1_RAW_CORRELATIONS'!W23*1.5,'1_RAW_CORRELATIONS'!X23*1.3,'1_RAW_CORRELATIONS'!Y23*1,'1_RAW_CORRELATIONS'!Z23*1,'1_RAW_CORRELATIONS'!AA23*1.1,'1_RAW_CORRELATIONS'!AB23*1,'1_RAW_CORRELATIONS'!AC23*0.9)-0 -> -0.056647146 | H23: =AVERAGE('1_RAW_CORRELATIONS'!AD23*1,'1_RAW_CORRELATIONS'!AE23*1.2,'1_RAW_CORRELATIONS'!AF23*1.1,'1_RAW_CORRELATIONS'!AG23*1.2,'1_RAW_CORRELATIONS'!AH23*1,'1_RAW_CORRELATIONS'!AI23*1,'1_RAW_CORRELATIONS'!AJ23*1.1,'1_RAW_CORRELATIONS'!AK23*1.1,'1_RAW_CORRELATIONS'!AL23*0.9)-0 -> -0.19273681 | I23: =AVERAGE('1_RAW_CORRELATIONS'!AM23*1,'1_RAW_CORRELATIONS'!AN23*1.2,'1_RAW_CORRELATIONS'!AO23*1,'1_RAW_CORRELATIONS'!AP23*1.3,'1_RAW_CORRELATIONS'!AQ23*1.2,'1_RAW_CORRELATIONS'!AR23*1.3,'1_RAW_CORRELATIONS'!AS23*1.1,'1_RAW_CORRELATIONS'!AT23*0.7)-0 -> -0.075908019 | J23: =AVERAGE('1_RAW_CORRELATIONS'!AU23*1.2,'1_RAW_CORRELATIONS'!AV23*1.2,'1_RAW_CORRELATIONS'!AW23*1.3,'1_RAW_CORRELATIONS'!AX23*1)-0 -> 0.056174797 | K23: =AVERAGE('1_RAW_CORRELATIONS'!AY23*1.3,'1_RAW_CORRELATIONS'!AZ23*1.1,'1_RAW_CORRELATIONS'!BA23*1,'1_RAW_CORRELATIONS'!BB23*0.9,'1_RAW_CORRELATIONS'!BC23*1.2)-0 -> 0.11444004 | L23: =IFERROR((D23-AVERAGE(D$4:D$23))/STDEV(D$4:D$23),0) -> -0.83938777 | M23: =IFERROR((E23-AVERAGE(E$4:E$23))/STDEV(E$4:E$23),0) -> -3.1088131 | N23: =IFERROR((F23-AVERAGE(F$4:F$23))/STDEV(F$4:F$23),0) -> -3.3761037 | O23: =IFERROR((G23-AVERAGE(G$4:G$23))/STDEV(G$4:G$23),0) -> -2.1099111 | P23: =IFERROR((H23-AVERAGE(H$4:H$23))/STDEV(H$4:H$23),0) -> -2.0202297 | Q23: =IFERROR((I23-AVERAGE(I$4:I$23))/STDEV(I$4:I$23),0) -> -0.099776161 | R23: =IFERROR((J23-AVERAGE(J$4:J$23))/STDEV(J$4:J$23),0) -> 0.63021911 | S23: =IFERROR((K23-AVERAGE(K$4:K$23))/STDEV(K$4:K$23),0) -> 2.5894252

Sheet 2_FRAME_MARKUP
A1: 2_FRAME_MARKUP — Разметка кадров (заполняется вручную перед анализом)
A2: Правило: каждый тег — отдельный столбец (1/0). 1 = тег присвоен, 0 = нет. frame_id и second тянутся из листа 1.
A3: frame_id | B3: second | C3: scene_description | D3: frame_image | E3: HOOK | F3: BRAND | G3: PRODUCT | H3: OFFER | I3: CTA | J3: LOGO
A4: ='1_RAW_CORRELATIONS'!A4 -> F01 | B4: ='1_RAW_CORRELATIONS'!B4 -> 1 | C4: ='1_RAW_CORRELATIONS'!C4 -> Who | E4: 0 | F4: 0 | G4: 0 | H4: 0 | I4: 0 | J4: 0
A5: ='1_RAW_CORRELATIONS'!A5 -> F02 | B5: ='1_RAW_CORRELATIONS'!B5 -> 2 | C5: ='1_RAW_CORRELATIONS'!C5 -> Who could have thought, | E5: 0 | F5: 0 | G5: 0 | H5: 0 | I5: 0 | J5: 0
A6: ='1_RAW_CORRELATIONS'!A6 -> F03 | B6: ='1_RAW_CORRELATIONS'!B6 -> 3 | C6: ='1_RAW_CORRELATIONS'!C6 -> thought, that the future would be | E6: 0 | F6: 0 | G6: 0 | H6: 0 | I6: 0 | J6: 1
A7: ='1_RAW_CORRELATIONS'!A7 -> F04 | B7: ='1_RAW_CORRELATIONS'!B7 -> 4 | C7: ='1_RAW_CORRELATIONS'!C7 -> would be exactly like this? | E7: 0 | F7: 0 | G7: 0 | H7: 0 | I7: 0 | J7: 1
A8: ='1_RAW_CORRELATIONS'!A8 -> F05 | B8: ='1_RAW_CORRELATIONS'!B8 -> 5 | C8: ='1_RAW_CORRELATIONS'!C8 -> like this? Concise, | E8: 0 | F8: 0 | G8: 0 | H8: 0 | I8: 0 | J8: 0
A9: ='1_RAW_CORRELATIONS'!A9 -> F06 | B9: ='1_RAW_CORRELATIONS'!B9 -> 6 | C9: ='1_RAW_CORRELATIONS'!C9 -> Concise, | E9: 0 | F9: 0 | G9: 0 | H9: 0 | I9: 0 | J9: 0
A10: ='1_RAW_CORRELATIONS'!A10 -> F07 | B10: ='1_RAW_CORRELATIONS'!B10 -> 7 | C10: ='1_RAW_CORRELATIONS'!C10 -> perfect, | E10: 0 | F10: 0 | G10: 0 | H10: 0 | I10: 0 | J10: 0
A11: ='1_RAW_CORRELATIONS'!A11 -> F08 | B11: ='1_RAW_CORRELATIONS'!B11 -> 8 | C11: ='1_RAW_CORRELATIONS'!C11 -> perfect, that design | E11: 0 | F11: 0 | G11: 0 | H11: 0 | I11: 0 | J11: 0
A12: ='1_RAW_CORRELATIONS'!A12 -> F09 | B12: ='1_RAW_CORRELATIONS'!B12 -> 9 | C12: ='1_RAW_CORRELATIONS'!C12 -> design would define | E12: 0 | F12: 0 | G12: 0 | H12: 0 | I12: 0 | J12: 0
A13: ='1_RAW_CORRELATIONS'!A13 -> F10 | B13: ='1_RAW_CORRELATIONS'!B13 -> 10 | C13: ='1_RAW_CORRELATIONS'!C13 -> define functionality, | E13: 0 | F13: 0 | G13: 0 | H13: 0 | I13: 0 | J13: 0
A14: ='1_RAW_CORRELATIONS'!A14 -> F11 | B14: ='1_RAW_CORRELATIONS'!B14 -> 11 | C14: ='1_RAW_CORRELATIONS'!C14 -> functionality, and technology | E14: 0 | F14: 0 | G14: 0 | H14: 0 | I14: 0 | J14: 0
A15: ='1_RAW_CORRELATIONS'!A15 -> F12 | B15: ='1_RAW_CORRELATIONS'!B15 -> 12 | C15: ='1_RAW_CORRELATIONS'!C15 -> technology would become an element | E15: 0 | F15: 0 | G15: 0 | H15: 0 | I15: 0 | J15: 0
... A23: ='1_RAW_CORRELATIONS'!A23 -> F20 | B23: ='1_RAW_CORRELATIONS'!B23 -> 20 | C23: ='1_RAW_CORRELATIONS'!C23 -> of the future. | E23: 0 | F23: 0 | G23: 0 | H23: 0 | I23: 0 | J23: 0

Sheet 5_WEIGHTS_REF
A1: 5_WEIGHTS_REF — Справочник весов (можно редактировать)
A2: Веса — экспертная эвристика v1. Синим выделены ячейки весов — их можно менять. После изменения пересчитать лист 3. Отрицательные веса означают штраф (penalty/load).
A3: index_id | B3: term | C3: weight | D3: role | E3: index_name | F3: note | G3: neurosynth_query
A4: ATT | B4: attention | C4: 1 | D4: anchor | E4: ATT — Внимание и захват взгляда | G4: attention
A5: ATT | B5: visual_attention | C5: 1.2 | D5: core | E5: ATT — Внимание и захват взгляда | G5: visual attention
A6: ATT | B6: attentional | C6: 1 | D6: core | E6: ATT — Внимание и захват взгляда | G6: attentional
A7: ATT | B7: orienting | C7: 1.1 | D7: core | E7: ATT — Внимание и захват взгляда | G7: orienting
A8: ATT | B8: target_detection | C8: 1 | D8: core | E8: ATT — Внимание и захват взгляда | G8: target detection
A9: ATT | B9: salience | C9: 1.2 | D9: core | E9: ATT — Внимание и захват взгляда | G9: salience
A10: ATT | B10: visual_stimuli | C10: 0.7 | D10: support | E10: ATT — Внимание и захват взгляда | G10: visual stimuli
A11: ATT | B11: distractor | C11: -1 | D11: penalty | E11: ATT — Внимание и захват взгляда | F11: Вычитается как штраф | G11: distractor
A12: AFF_A | B12: arousal | C12: 1.3 | D12: core | E12: AFF-A — Эмоциональная интенсивность (Arousal) | G12: arousal
A13: AFF_A | B13: affective | C13: 1 | D13: core | E13: AFF-A — Эмоциональная интенсивность (Arousal) | G13: affective
A14: AFF_A | B14: emotional | C14: 0.5 | D14: anchor | E14: AFF-A — Эмоциональная интенсивность (Arousal) | G14: emotional
A15: AFF_A | B15: emotional_stimuli | C15: 0.6 | D15: core | E15: AFF-A — Эмоциональная интенсивность (Arousal) | F15: Новый терм v1.3 — заменяет 'emotion' для большей специфичности | G15: emotional stimuli
A16: AFF_A | B16: emotional_responses | C16: 0.6 | D16: core | E16: AFF-A — Эмоциональная интенсивность (Arousal) | F16: Новый терм v1.3 — заменяет 'emotion' для большей специфичности | G16: emotional responses
A17: AFF_V | B17: valence | C17: 1 | D17: anchor | E17: AFF-V — Негативная эмоциональная окраска | G17: valence
A18: AFF_V | B18: negative_affect | C18: 1.2 | D18: penalty | E18: AFF-V — Негативная эмоциональная окраска | F18: Вычитается как штраф | G18: negative affect
A19: AFF_V | B19: disgust | C19: 1.5 | D19: penalty | E19: AFF-V — Негативная эмоциональная окраска | F19: Вычитается как штраф | G19: disgust
A20: AFF_V | B20: fear | C20: 0.6 | D20: penalty | E20: AFF-V — Негативная эмоциональная окраска | F20: Вычитается как штраф | G20: fear
A21: AFF_V | B21: anxiety | C21: 0.5 | D21: penalty | E21: AFF-V — Негативная эмоциональная окраска | F21: Вычитается как штраф | G21: anxiety
A22: MEM | B22: encoding | C22: 1.5 | D22: core | E22: MEM — Потенциал запоминания | G22: encoding
A23: MEM | B23: subsequent_memory | C23: 1.3 | D23: core | E23: MEM — Потенциал запоминания | G23: subsequent memory
A24: MEM | B24: episodic_memory | C24: 1 | D24: core | E24: MEM — Потенциал запоминания | G24: episodic memory
A25: MEM | B25: semantic_memory | C25: 1 | D25: core | E25: MEM — Потенциал запоминания | G25: semantic memory
A26: MEM | B26: recall | C26: 1.1 | D26: core | E26: MEM — Потенциал запоминания | G26: recall
A27: MEM | B27: recognition | C27: 1 | D27: core | E27: MEM — Потенциал запоминания | G27: recognition
